Workbook

Sheet Round1
A2: Round 1 - Tournament Standings
B3: TOURNAMENT STANDINGS
A6: RANK | B6: PLAYER | C6: SCORE | D6: POINTS
A7: ='RND 1 STBL'!AD14 -> 1 | B7: ='RND 1 STBL'!AE14 -> STONES | C7: ='RND 1 STBL'!AF14 -> 49 | D7: ='RND 1 STBL'!AG14 -> 24
A8: ='RND 1 STBL'!AD15 -> 2 | B8: ='RND 1 STBL'!AE15 -> BELLIS | C8: ='RND 1 STBL'!AF15 -> 36 | D8: ='RND 1 STBL'!AG15 -> 21
A9: ='RND 1 STBL'!AD16 -> 3 | B9: ='RND 1 STBL'!AE16 -> REILLY | C9: ='RND 1 STBL'!AF16 -> 25 | D9: ='RND 1 STBL'!AG16 -> 18
A10: ='RND 1 STBL'!AD17 -> 4 | B10: ='RND 1 STBL'!AE17 -> FINDLAY | C10: ='RND 1 STBL'!AF17 -> 24 | D10: ='RND 1 STBL'!AG17 -> 15
A11: ='RND 1 STBL'!AD18 -> 5 | B11: ='RND 1 STBL'!AE18 -> HOLLANDS | C11: ='RND 1 STBL'!AF18 -> 18 | D11: ='RND 1 STBL'!AG18 -> 12
A12: ='RND 1 STBL'!AD19 -> 6 | B12: ='RND 1 STBL'!AE19 -> DEY | C12: ='RND 1 STBL'!AF19 -> 17 | D12: ='RND 1 STBL'!AG19 -> 7.5
A13: ='RND 1 STBL'!AD20 -> 7 | B13: ='RND 1 STBL'!AE20 -> DONOVAN | C13: ='RND 1 STBL'!AF20 -> 17 | D13: ='RND 1 STBL'!AG20 -> 7.5
A14: ='RND 1 STBL'!AD21 -> 8 | B14: ='RND 1 STBL'!AE21 -> LAING | C14: ='RND 1 STBL'!AF21 -> 16 | D14: ='RND 1 STBL'!AG21 -> 3
A21: Round 1 - Strokes
A22: PLAYERS | B22: HCP | D22: HOLE | E22: 1 | F22: 2 | G22: 3 | H22: 4 | I22: 5 | J22: 6 | K22: 7 | L22: 8 | M22: 9 | N22: 10 | O22: 11 | P22: 12 | Q22: 13 | R22: 14 | S22: 15 | T22: 16 | U22: 17 | V22: 18 | W22: TOTAL
D23: PAR | E23: ='RND 1 STBL'!C5 -> 4 | F23: ='RND 1 STBL'!D5 -> 3 | G23: ='RND 1 STBL'!E5 -> 4 | H23: ='RND 1 STBL'!F5 -> 4 | I23: ='RND 1 STBL'!G5 -> 4 | J23: ='RND 1 STBL'!H5 -> 4 | K23: ='RND 1 STBL'!I5 -> 4 | L23: ='RND 1 STBL'!J5 -> 3 | ... V23: ='RND 1 STBL'!T5 -> 4
D24: S.I | E24: ='RND 1 STBL'!C6 -> 9 | F24: ='RND 1 STBL'!D6 -> 13 | G24: ='RND 1 STBL'!E6 -> 5 | H24: ='RND 1 STBL'!F6 -> 1 | I24: ='RND 1 STBL'!G6 -> 11 | J24: ='RND 1 STBL'!H6 -> 15 | K24: ='RND 1 STBL'!I6 -> 7 | L24: ='RND 1 STBL'!J6 -> 17 | ... V24: ='RND 1 STBL'!T6 -> 2
A26: ='RND 1 STBL'!A7 -> BELLIS | B26: ='RND 1 STBL'!B7 -> 18 | E26: ='RND 1 STBL'!C7 -> 5 | F26: ='RND 1 STBL'!D7 -> 5 | G26: ='RND 1 STBL'!E7 -> 5 | H26: ='RND 1 STBL'!F7 -> 5 | I26: ='RND 1 STBL'!G7 -> 5 | J26: ='RND 1 STBL'!H7 -> 5 | K26: ='RND 1 STBL'!I7 -> 5 | L26: ='RND 1 STBL'!J7 -> 5 | ... W26: ='RND 1 STBL'!U7 -> 90
A27: ='RND 1 STBL'!A8 -> DEY | B27: ='RND 1 STBL'!B8 -> 18 | E27: ='RND 1 STBL'!C8 -> 5 | F27: ='RND 1 STBL'!D8 -> 9 | G27: ='RND 1 STBL'!E8 -> 6 | H27: ='RND 1 STBL'!F8 -> 9 | I27: ='RND 1 STBL'!G8 -> 6 | J27: ='RND 1 STBL'!H8 -> 9 | K27: ='RND 1 STBL'!I8 -> 6 | L27: ='RND 1 STBL'!J8 -> 9 | ... W27: ='RND 1 STBL'!U8 -> 59
A28: ='RND 1 STBL'!A9 -> DONOVAN | B28: ='RND 1 STBL'!B9 -> 18 | E28: ='RND 1 STBL'!C9 -> 5 | F28: ='RND 1 STBL'!D9 -> 9 | G28: ='RND 1 STBL'!E9 -> 6 | H28: ='RND 1 STBL'!F9 -> 9 | I28: ='RND 1 STBL'!G9 -> 6 | J28: ='RND 1 STBL'!H9 -> 9 | K28: ='RND 1 STBL'!I9 -> 6 | L28: ='RND 1 STBL'!J9 -> 9 | ... W28: ='RND 1 STBL'!U9 -> 59
A29: ='RND 1 STBL'!A10 -> FINDLAY | B29: ='RND 1 STBL'!B10 -> 18 | E29: ='RND 1 STBL'!C10 -> 5 | F29: ='RND 1 STBL'!D10 -> 4 | G29: ='RND 1 STBL'!E10 -> 6 | H29: ='RND 1 STBL'!F10 -> 4 | I29: ='RND 1 STBL'!G10 -> 6 | J29: ='RND 1 STBL'!H10 -> 9 | K29: ='RND 1 STBL'!I10 -> 6 | L29: ='RND 1 STBL'!J10 -> 4 | ... W29: ='RND 1 STBL'!U10 -> 44
A30: ='RND 1 STBL'!A11 -> HOLLANDS | B30: ='RND 1 STBL'!B11 -> 18 | E30: ='RND 1 STBL'!C11 -> 6 | F30: ='RND 1 STBL'!D11 -> 4 | G30: ='RND 1 STBL'!E11 -> 6 | H30: ='RND 1 STBL'!F11 -> 9 | I30: ='RND 1 STBL'!G11 -> 6 | J30: ='RND 1 STBL'!H11 -> 9 | K30: ='RND 1 STBL'!I11 -> 6 | L30: ='RND 1 STBL'!J11 -> 9 | ... W30: ='RND 1 STBL'!U11 -> 55
A31: ='RND 1 STBL'!A12 -> LAING | B31: ='RND 1 STBL'!B12 -> 18 | E31: ='RND 1 STBL'!C12 -> 6 | F31: ='RND 1 STBL'!D12 -> 9 | G31: ='RND 1 STBL'!E12 -> 6 | H31: ='RND 1 STBL'!F12 -> 9 | I31: ='RND 1 STBL'!G12 -> 6 | J31: ='RND 1 STBL'!H12 -> 9 | K31: ='RND 1 STBL'!I12 -> 6 | L31: ='RND 1 STBL'!J12 -> 9 | ... W31: ='RND 1 STBL'!U12 -> 60
A32: ='RND 1 STBL'!A13 -> REILLY | B32: ='RND 1 STBL'!B13 -> 18 | E32: ='RND 1 STBL'!C13 -> 6 | F32: ='RND 1 STBL'!D13 -> 0 | G32: ='RND 1 STBL'!E13 -> 0 | H32: ='RND 1 STBL'!F13 -> 0 | I32: ='RND 1 STBL'!G13 -> 0 | J32: ='RND 1 STBL'!H13 -> 0 | K32: ='RND 1 STBL'!I13 -> 0 | L32: ='RND 1 STBL'!J13 -> 0 | ... W32: ='RND 1 STBL'!U13 -> 6
A33: ='RND 1 STBL'!A14 -> STONES | B33: ='RND 1 STBL'!B14 -> 18 | E33: ='RND 1 STBL'!C14 -> 6 | F33: ='RND 1 STBL'!D14 -> 4 | G33: ='RND 1 STBL'!E14 -> 4 | H33: ='RND 1 STBL'!F14 -> 7 | I33: ='RND 1 STBL'!G14 -> 4 | J33: ='RND 1 STBL'!H14 -> 4 | K33: ='RND 1 STBL'!I14 -> 4 | L33: ='RND 1 STBL'!J14 -> 4 | ... W33: ='RND 1 STBL'!U14 -> 77
A37: Round 1 - Stableford Points
A38: PLAYERS | B38: HCP | D38: HOLE | E38: 1 | F38: 2 | G38: 3 | H38: 4 | I38: 5 | J38: 6 | K38: 7 | L38: 8 | M38: 9 | N38: 10 | O38: 11 | P38: 12 | Q38: 13 | R38: 14 | S38: 15 | T38: 16 | U38: 17 | V38: 18 | W38: TOTAL
D39: PAR | E39: =E23 -> 4 | F39: =F23 -> 3 | G39: =G23 -> 4 | H39: =H23 -> 4 | I39: =I23 -> 4 | J39: =J23 -> 4 | K39: =K23 -> 4 | L39: =L23 -> 3 | ... V39: =V23 -> 4
D40: S.I | E40: =E24 -> 9 | F40: =F24 -> 13 | G40: =G24 -> 5 | H40: =H24 -> 1 | I40: =I24 -> 11 | J40: =J24 -> 15 | K40: =K24 -> 7 | L40: =L24 -> 17 | ... V40: =V24 -> 2
A42: =A26 -> BELLIS | B42: =B26 -> 18 | E42: ='RND 1 STBL'!C55 -> 2 | F42: ='RND 1 STBL'!D55 -> 1 | G42: ='RND 1 STBL'!E55 -> 2 | H42: ='RND 1 STBL'!F55 -> 2 | I42: ='RND 1 STBL'!G55 -> 2 | J42: ='RND 1 STBL'!H55 -> 2 | K42: ='RND 1 STBL'!I55 -> 2 | L42: ='RND 1 STBL'!J55 -> 1 | ... W42: ='RND 1 STBL'!U55 -> 36
A43: =A27 -> DEY | B43: =B27 -> 18 | E43: ='RND 1 STBL'!C56 -> 2 | F43: ='RND 1 STBL'!D56 -> 0 | G43: ='RND 1 STBL'!E56 -> 1 | H43: ='RND 1 STBL'!F56 -> 0 | I43: ='RND 1 STBL'!G56 -> 1 | J43: ='RND 1 STBL'!H56 -> 0 | K43: ='RND 1 STBL'!I56 -> 1 | L43: ='RND 1 STBL'!J56 -> 0 | ... W43: ='RND 1 STBL'!U56 -> 17
A44: =A28 -> DONOVAN | B44: =B28 -> 18 | E44: ='RND 1 STBL'!C57 -> 2 | F44: ='RND 1 STBL'!D57 -> 0 | G44: ='RND 1 STBL'!E57 -> 1 | H44: ='RND 1 STBL'!F57 -> 0 | I44: ='RND 1 STBL'!G57 -> 1 | J44: ='RND 1 STBL'!H57 -> 0 | K44: ='RND 1 STBL'!I57 -> 1 | L44: ='RND 1 STBL'!J57 -> 0 | ... W44: ='RND 1 STBL'!U57 -> 17
A45: =A29 -> FINDLAY | B45: =B29 -> 18 | E45: ='RND 1 STBL'!C58 -> 2 | F45: ='RND 1 STBL'!D58 -> 2 | G45: ='RND 1 STBL'!E58 -> 1 | H45: ='RND 1 STBL'!F58 -> 3 | I45: ='RND 1 STBL'!G58 -> 1 | J45: ='RND 1 STBL'!H58 -> 0 | K45: ='RND 1 STBL'!I58 -> 1 | L45: ='RND 1 STBL'!J58 -> 2 | ... W45: ='RND 1 STBL'!U58 -> 24
A46: =A30 -> HOLLANDS | B46: =B30 -> 18 | E46: ='RND 1 STBL'!C59 -> 1 | F46: ='RND 1 STBL'!D59 -> 2 | G46: ='RND 1 STBL'!E59 -> 1 | H46: ='RND 1 STBL'!F59 -> 0 | I46: ='RND 1 STBL'!G59 -> 1 | J46: ='RND 1 STBL'!H59 -> 0 | K46: ='RND 1 STBL'!I59 -> 1 | L46: ='RND 1 STBL'!J59 -> 0 | ... W46: ='RND 1 STBL'!U59 -> 18
A47: =A31 -> LAING | B47: =B31 -> 18 | E47: ='RND 1 STBL'!C60 -> 1 | F47: ='RND 1 STBL'!D60 -> 0 | G47: ='RND 1 STBL'!E60 -> 1 | H47: ='RND 1 STBL'!F60 -> 0 | I47: ='RND 1 STBL'!G60 -> 1 | J47: ='RND 1 STBL'!H60 -> 0 | K47: ='RND 1 STBL'!I60 -> 1 | L47: ='RND 1 STBL'!J60 -> 0 | ... W47: ='RND 1 STBL'!U60 -> 16
A48: =A32 -> REILLY | B48: =B32 -> 18 | E48: ='RND 1 STBL'!C61 -> 1 | F48: ='RND 1 STBL'!D61 -> 6 | G48: ='RND 1 STBL'!E61 -> 0 | H48: ='RND 1 STBL'!F61 -> 0 | I48: ='RND 1 STBL'!G61 -> 0 | J48: ='RND 1 STBL'!H61 -> 0 | K48: ='RND 1 STBL'!I61 -> 0 | L48: ='RND 1 STBL'!J61 -> 6 | ... W48: ='RND 1 STBL'!U61 -> 25
A49: =A33 -> STONES | B49: =B33 -> 18 | E49: ='RND 1 STBL'!C62 -> 1 | F49: ='RND 1 STBL'!D62 -> 2 | G49: ='RND 1 STBL'!E62 -> 3 | H49: ='RND 1 STBL'!F62 -> 0 | I49: ='RND 1 STBL'!G62 -> 3 | J49: ='RND 1 STBL'!H62 -> 3 | K49: ='RND 1 STBL'!I62 -> 3 | L49: ='RND 1 STBL'!J62 -> 2 | ... W49: ='RND 1 STBL'!U62 -> 49

Sheet RND 1 STBL
A1: ROUND 1 SCORECARD & POINTS Blue Lakes | Y1: TOURNAMENT RANKER
A4: PLAYERS | B4: HCP | C4: 1 | D4: 2 | E4: 3 | F4: 4 | G4: 5 | H4: 6 | I4: 7 | J4: 8 | K4: 9 | L4: 10 | M4: 11 | N4: 12 | O4: 13 | P4: 14 | Q4: 15 | R4: 16 | S4: 17 | T4: 18 | U4: TOTAL | V4: SCORECARD | Y4: =A7 -> BELLIS | Z4: =U55 -> 36 | AA4: =RANK(Z4,$Z$4:$Z$11,0) -> 2 | AD4: =IF(AA4=1,24,0)+(IF(AA4=2,21,0))+(IF(AA4=3,18,0))+(IF(AA4=4,15,0))+(IF(AA4=5,12,0))+(IF(AA4=6,9,0))+(IF(AA4=7,6,0))+(IF(AA4=8,3,0)) -> 21 | AE4: =COUNTIF($AD$4:$AD$11,AD4) -> 1 | AF4: =SUMIF($AD$4:$AD$11,AD4) -> 21 | AG4: =IF(AE4=3,AF4/3-3,0)+IF(AE4=2,AF4/2-1.5,0)+IF(AE4=1,AF4,0)+IF(AE4=4,AF4/4-4.5,0)+IF(AE4=5,AF4/5-6,0)+IF(AE4=6,AF4/6-7.5,0)+IF(AE4=7,AF4/7-9,0)+IF(AE4=8,AF4/8-10.5,0) -> 21
B5: PAR | C5: 4 | D5: 3 | E5: 4 | F5: 4 | G5: 4 | H5: 4 | I5: 4 | J5: 3 | K5: 5 | L5: 5 | M5: 4 | N5: 3 | O5: 5 | P5: 4 | Q5: 5 | R5: 4 | S5: 3 | T5: 4 | Y5: =A8 -> DEY | Z5: =U56 -> 17 | AA5: =RANK(Z5,$Z$4:$Z$11,0) -> 6 | AD5: =IF(AA5=1,24,0)+(IF(AA5=2,21,0))+(IF(AA5=3,18,0))+(IF(AA5=4,15,0))+(IF(AA5=5,12,0))+(IF(AA5=6,9,0))+(IF(AA5=7,6,0))+(IF(AA5=8,3,0)) -> 9 | AE5: =COUNTIF($AD$4:$AD$11,AD5) -> 2 | AF5: =SUMIF($AD$4:$AD$11,AD5) -> 18 | AG5: =IF(AE5=3,AF5/3-3,0)+IF(AE5=2,AF5/2-1.5,0)+IF(AE5=1,AF5,0)+IF(AE5=4,AF5/4-4.5,0)+IF(AE5=5,AF5/5-6,0)+IF(AE5=6,AF5/6-7.5,0)+IF(AE5=7,AF5/7-9,0)+IF(AE5=8,AF5/8-10.5,0) -> 7.5
B6: S.I | C6: 9 | D6: 13 | E6: 5 | F6: 1 | G6: 11 | H6: 15 | I6: 7 | J6: 17 | K6: 3 | L6: 4 | M6: 14 | N6: 16 | O6: 10 | P6: 6 | Q6: 8 | R6: 12 | S6: 18 | T6: 2 | Y6: =A9 -> DONOVAN | Z6: =U57 -> 17 | AA6: =RANK(Z6,$Z$4:$Z$11,0) -> 6 | AD6: =IF(AA6=1,24,0)+(IF(AA6=2,21,0))+(IF(AA6=3,18,0))+(IF(AA6=4,15,0))+(IF(AA6=5,12,0))+(IF(AA6=6,9,0))+(IF(AA6=7,6,0))+(IF(AA6=8,3,0)) -> 9 | AE6: =COUNTIF($AD$4:$AD$11,AD6) -> 2 | AF6: =SUMIF($AD$4:$AD$11,AD6) -> 18 | AG6: =IF(AE6=3,AF6/3-3,0)+IF(AE6=2,AF6/2-1.5,0)+IF(AE6=1,AF6,0)+IF(AE6=4,AF6/4-4.5,0)+IF(AE6=5,AF6/5-6,0)+IF(AE6=6,AF6/6-7.5,0)+IF(AE6=7,AF6/7-9,0)+IF(AE6=8,AF6/8-10.5,0) -> 7.5
A7: BELLIS | B7: 18 | C7: 5 | D7: 5 | E7: 5 | F7: 5 | G7: 5 | H7: 5 | I7: 5 | J7: 5 | K7: 5 | L7: 5 | M7: 5 | N7: 5 | O7: 5 | P7: 5 | Q7: 5 | R7: 5 | S7: 5 | T7: 5 | U7: =SUM(C7:T7) -> 90 | Y7: =A10 -> FINDLAY | Z7: =U58 -> 24 | AA7: =RANK(Z7,$Z$4:$Z$11,0) -> 4 | AD7: =IF(AA7=1,24,0)+(IF(AA7=2,21,0))+(IF(AA7=3,18,0))+(IF(AA7=4,15,0))+(IF(AA7=5,12,0))+(IF(AA7=6,9,0))+(IF(AA7=7,6,0))+(IF(AA7=8,3,0)) -> 15 | AE7: =COUNTIF($AD$4:$AD$11,AD7) -> 1 | AF7: =SUMIF($AD$4:$AD$11,AD7) -> 15 | AG7: =IF(AE7=3,AF7/3-3,0)+IF(AE7=2,AF7/2-1.5,0)+IF(AE7=1,AF7,0)+IF(AE7=4,AF7/4-4.5,0)+IF(AE7=5,AF7/5-6,0)+IF(AE7=6,AF7/6-7.5,0)+IF(AE7=7,AF7/7-9,0)+IF(AE7=8,AF7/8-10.5,0) -> 15
A8: DEY | B8: 18 | C8: 5 | D8: 9 | E8: 6 | F8: 9 | G8: 6 | H8: 9 | I8: 6 | J8: 9 | K8: 0 | L8: 0 | M8: 0 | N8: 0 | O8: 0 | P8: 0 | Q8: 0 | R8: 0 | S8: 0 | T8: 0 | U8: =SUM(C8:T8) -> 59 | Y8: =A11 -> HOLLANDS | Z8: =U59 -> 18 | AA8: =RANK(Z8,$Z$4:$Z$11,0) -> 5 | AD8: =IF(AA8=1,24,0)+(IF(AA8=2,21,0))+(IF(AA8=3,18,0))+(IF(AA8=4,15,0))+(IF(AA8=5,12,0))+(IF(AA8=6,9,0))+(IF(AA8=7,6,0))+(IF(AA8=8,3,0)) -> 12 | AE8: =COUNTIF($AD$4:$AD$11,AD8) -> 1 | AF8: =SUMIF($AD$4:$AD$11,AD8) -> 12 | AG8: =IF(AE8=3,AF8/3-3,0)+IF(AE8=2,AF8/2-1.5,0)+IF(AE8=1,AF8,0)+IF(AE8=4,AF8/4-4.5,0)+IF(AE8=5,AF8/5-6,0)+IF(AE8=6,AF8/6-7.5,0)+IF(AE8=7,AF8/7-9,0)+IF(AE8=8,AF8/8-10.5,0) -> 12
A9: DONOVAN | B9: 18 | C9: 5 | D9: 9 | E9: 6 | F9: 9 | G9: 6 | H9: 9 | I9: 6 | J9: 9 | K9: 0 | L9: 0 | M9: 0 | N9: 0 | O9: 0 | P9: 0 | Q9: 0 | R9: 0 | S9: 0 | T9: 0 | U9: =SUM(C9:T9) -> 59 | Y9: =A12 -> LAING | Z9: =U60 -> 16 | AA9: =RANK(Z9,$Z$4:$Z$11,0) -> 8 | AD9: =IF(AA9=1,24,0)+(IF(AA9=2,21,0))+(IF(AA9=3,18,0))+(IF(AA9=4,15,0))+(IF(AA9=5,12,0))+(IF(AA9=6,9,0))+(IF(AA9=7,6,0))+(IF(AA9=8,3,0)) -> 3 | AE9: =COUNTIF($AD$4:$AD$11,AD9) -> 1 | AF9: =SUMIF($AD$4:$AD$11,AD9) -> 3 | AG9: =IF(AE9=3,AF9/3-3,0)+IF(AE9=2,AF9/2-1.5,0)+IF(AE9=1,AF9,0)+IF(AE9=4,AF9/4-4.5,0)+IF(AE9=5,AF9/5-6,0)+IF(AE9=6,AF9/6-7.5,0)+IF(AE9=7,AF9/7-9,0)+IF(AE9=8,AF9/8-10.5,0) -> 3
A10: FINDLAY | B10: 18 | C10: 5 | D10: 4 | E10: 6 | F10: 4 | G10: 6 | H10: 9 | I10: 6 | J10: 4 | K10: 0 | L10: 0 | M10: 0 | N10: 0 | O10: 0 | P10: 0 | Q10: 0 | R10: 0 | S10: 0 | T10: 0 | U10: =SUM(C10:T10) -> 44 | Y10: =A13 -> REILLY | Z10: =U61 -> 25 | AA10: =RANK(Z10,$Z$4:$Z$11,0) -> 3 | AD10: =IF(AA10=1,24,0)+(IF(AA10=2,21,0))+(IF(AA10=3,18,0))+(IF(AA10=4,15,0))+(IF(AA10=5,12,0))+(IF(AA10=6,9,0))+(IF(AA10=7,6,0))+(IF(AA10=8,3,0)) -> 18 | AE10: =COUNTIF($AD$4:$AD$11,AD10) -> 1 | AF10: =SUMIF($AD$4:$AD$11,AD10) -> 18 | AG10: =IF(AE10=3,AF10/3-3,0)+IF(AE10=2,AF10/2-1.5,0)+IF(AE10=1,AF10,0)+IF(AE10=4,AF10/4-4.5,0)+IF(AE10=5,AF10/5-6,0)+IF(AE10=6,AF10/6-7.5,0)+IF(AE10=7,AF10/7-9,0)+IF(AE10=8,AF10/8-10.5,0) -> 18
A11: HOLLANDS | B11: 18 | C11: 6 | D11: 4 | E11: 6 | F11: 9 | G11: 6 | H11: 9 | I11: 6 | J11: 9 | K11: 0 | L11: 0 | M11: 0 | N11: 0 | O11: 0 | P11: 0 | Q11: 0 | R11: 0 | S11: 0 | T11: 0 | U11: =SUM(C11:T11) -> 55 | Y11: =A14 -> STONES | Z11: =U62 -> 49 | AA11: =RANK(Z11,$Z$4:$Z$11,0) -> 1 | AD11: =IF(AA11=1,24,0)+(IF(AA11=2,21,0))+(IF(AA11=3,18,0))+(IF(AA11=4,15,0))+(IF(AA11=5,12,0))+(IF(AA11=6,9,0))+(IF(AA11=7,6,0))+(IF(AA11=8,3,0)) -> 24 | AE11: =COUNTIF($AD$4:$AD$11,AD11) -> 1 | AF11: =SUMIF($AD$4:$AD$11,AD11) -> 24 | AG11: =IF(AE11=3,AF11/3-3,0)+IF(AE11=2,AF11/2-1.5,0)+IF(AE11=1,AF11,0)+IF(AE11=4,AF11/4-4.5,0)+IF(AE11=5,AF11/5-6,0)+IF(AE11=6,AF11/6-7.5,0)+IF(AE11=7,AF11/7-9,0)+IF(AE11=8,AF11/8-10.5,0) -> 24
A12: LAING | B12: 18 | C12: 6 | D12: 9 | E12: 6 | F12: 9 | G12: 6 | H12: 9 | I12: 6 | J12: 9 | K12: 0 | L12: 0 | M12: 0 | N12: 0 | O12: 0 | P12: 0 | Q12: 0 | R12: 0 | S12: 0 | T12: 0 | U12: =SUM(C12:T12) -> 60
A13: REILLY | B13: 18 | C13: 6 | D13: 0 | E13: 0 | F13: 0 | G13: 0 | H13: 0 | I13: 0 | J13: 0 | K13: 0 | L13: 0 | M13: 0 | N13: 0 | O13: 0 | P13: 0 | Q13: 0 | R13: 0 | S13: 0 | T13: 0 | U13: =SUM(C13:T13) -> 6
A14: STONES | B14: 18 | C14: 6 | D14: 4 | E14: 4 | F14: 7 | G14: 4 | H14: 4 | I14: 4 | J14: 4 | K14: 4 | L14: 4 | M14: 4 | N14: 4 | O14: 4 | P14: 4 | Q14: 4 | R14: 4 | S14: 4 | T14: 4 | U14: =SUM(C14:T14) -> 77 | Y14: =Y4 -> BELLIS | Z14: =Z4 -> 36 | AA14: =AG4 -> 21 | AB14: =RANK(Z14,$Z$14:$Z$21,0)+COUNTIF($Z$14:Z14,Z14)-1 -> 2 | AD14: 1 | AE14: =INDEX($Y$14:$AB$21,MATCH(AD14,$AB$14:$AB$21,0),1) -> STONES | AF14: =INDEX($Y$14:$AB$21,MATCH(AD14,$AB$14:$AB$21,0),2) -> 49 | AG14: =INDEX($Y$14:$AB$21,MATCH(AD14,$AB$14:$AB$21,0),3) -> 24
Y15: =Y5 -> DEY | Z15: =Z5 -> 17 | AA15: =AG5 -> 7.5 | AB15: =RANK(Z15,$Z$14:$Z$21,0)+COUNTIF($Z$14:Z15,Z15)-1 -> 6 | AD15: 2 | AE15: =INDEX($Y$14:$AB$21,MATCH(AD15,$AB$14:$AB$21,0),1) -> BELLIS | AF15: =INDEX($Y$14:$AB$21,MATCH(AD15,$AB$14:$AB$21,0),2) -> 36 | AG15: =INDEX($Y$14:$AB$21,MATCH(AD15,$AB$14:$AB$21,0),3) -> 21
C16: =C4 -> 1 | D16: =D4 -> 2 | E16: =E4 -> 3 | F16: =F4 -> 4 | G16: =G4 -> 5 | H16: =H4 -> 6 | I16: =I4 -> 7 | J16: =J4 -> 8 | ... T16: =T4 -> 18 | U16: TOTAL | V16: HCP STRKS | Y16: =Y6 -> DONOVAN | Z16: =Z6 -> 17 | AA16: =AG6 -> 7.5 | AB16: =RANK(Z16,$Z$14:$Z$21,0)+COUNTIF($Z$14:Z16,Z16)-1 -> 7 | AD16: 3 | AE16: =INDEX($Y$14:$AB$21,MATCH(AD16,$AB$14:$AB$21,0),1) -> REILLY | AF16: =INDEX($Y$14:$AB$21,MATCH(AD16,$AB$14:$AB$21,0),2) -> 25 | AG16: =INDEX($Y$14:$AB$21,MATCH(AD16,$AB$14:$AB$21,0),3) -> 18
C17: =C5 -> 4 | D17: =D5 -> 3 | E17: =E5 -> 4 | F17: =F5 -> 4 | G17: =G5 -> 4 | H17: =H5 -> 4 | I17: =I5 -> 4 | J17: =J5 -> 3 | ... T17: =T5 -> 4 | Y17: =Y7 -> FINDLAY | Z17: =Z7 -> 24 | AA17: =AG7 -> 15 | AB17: =RANK(Z17,$Z$14:$Z$21,0)+COUNTIF($Z$14:Z17,Z17)-1 -> 4 | AD17: 4 | AE17: =INDEX($Y$14:$AB$21,MATCH(AD17,$AB$14:$AB$21,0),1) -> FINDLAY | AF17: =INDEX($Y$14:$AB$21,MATCH(AD17,$AB$14:$AB$21,0),2) -> 24 | AG17: =INDEX($Y$14:$AB$21,MATCH(AD17,$AB$14:$AB$21,0),3) -> 15
C18: =C6 -> 9 | D18: =D6 -> 13 | E18: =E6 -> 5 | F18: =F6 -> 1 | G18: =G6 -> 11 | H18: =H6 -> 15 | I18: =I6 -> 7 | J18: =J6 -> 17 | ... T18: =T6 -> 2 | Y18: =Y8 -> HOLLANDS | Z18: =Z8 -> 18 | AA18: =AG8 -> 12 | AB18: =RANK(Z18,$Z$14:$Z$21,0)+COUNTIF($Z$14:Z18,Z18)-1 -> 5 | AD18: 5 | AE18: =INDEX($Y$14:$AB$21,MATCH(AD18,$AB$14:$AB$21,0),1) -> HOLLANDS | AF18: =INDEX($Y$14:$AB$21,MATCH(AD18,$AB$14:$AB$21,0),2) -> 18 | AG18: =INDEX($Y$14:$AB$21,MATCH(AD18,$AB$14:$AB$21,0),3) -> 12
A19: =A7 -> BELLIS | B19: =B7 -> 18 | C19: =IF($B$19>=C18,"●","")&(IF($B$19-18>=C18,"●","")) -> ● | D19: =IF($B$19>=D18,"●","")&(IF($B$19-18>=D18,"●","")) -> ● | E19: =IF($B$19>=E18,"●","")&(IF($B$19-18>=E18,"●","")) -> ● | F19: =IF($B$19>=F18,"●","")&(IF($B$19-18>=F18,"●","")) -> ● | G19: =IF($B$19>=G18,"●","")&(IF($B$19-18>=G18,"●","")) -> ● | H19: =IF($B$19>=H18,"●","")&(IF($B$19-18>=H18,"●","")) -> ● | I19: =IF($B$19>=I18,"●","")&(IF($B$19-18>=I18,"●","")) -> ● | J19: =IF($B$19>=J18,"●","")&(IF($B$19-18>=J18,"●","")) -> ● | ... T19: =IF($B$19>=T18,"●","")&(IF($B$19-18>=T18,"●","")) -> ● | Y19: =Y9 -> LAING | Z19: =Z9 -> 16 | AA19: =AG9 -> 3 | AB19: =RANK(Z19,$Z$14:$Z$21,0)+COUNTIF($Z$14:Z19,Z19)-1 -> 8 | AD19: 6 | AE19: =INDEX($Y$14:$AB$21,MATCH(AD19,$AB$14:$AB$21,0),1) -> DEY | AF19: =INDEX($Y$14:$AB$21,MATCH(AD19,$AB$14:$AB$21,0),2) -> 17 | AG19: =INDEX($Y$14:$AB$21,MATCH(AD19,$AB$14:$AB$21,0),3) -> 7.5
A20: =A8 -> DEY | B20: =B8 -> 18 | C20: =IF($B$20>=C18,"●","")&(IF($B$20-18>=C18,"●","")) -> ● | D20: =IF($B$20>=D18,"●","")&(IF($B$20-18>=D18,"●","")) -> ● | E20: =IF($B$20>=E18,"●","")&(IF($B$20-18>=E18,"●","")) -> ● | F20: =IF($B$20>=F18,"●","")&(IF($B$20-18>=F18,"●","")) -> ● | G20: =IF($B$20>=G18,"●","")&(IF($B$20-18>=G18,"●","")) -> ● | H20: =IF($B$20>=H18,"●","")&(IF($B$20-18>=H18,"●","")) -> ● | I20: =IF($B$20>=I18,"●","")&(IF($B$20-18>=I18,"●","")) -> ● | J20: =IF($B$20>=J18,"●","")&(IF($B$20-18>=J18,"●","")) -> ● | ... T20: =IF($B$20>=T18,"●","")&(IF($B$20-18>=T18,"●","")) -> ● | Y20: =Y10 -> REILLY | Z20: =Z10 -> 25 | AA20: =AG10 -> 18 | AB20: =RANK(Z20,$Z$14:$Z$21,0)+COUNTIF($Z$14:Z20,Z20)-1 -> 3 | AD20: 7 | AE20: =INDEX($Y$14:$AB$21,MATCH(AD20,$AB$14:$AB$21,0),1) -> DONOVAN | AF20: =INDEX($Y$14:$AB$21,MATCH(AD20,$AB$14:$AB$21,0),2) -> 17 | AG20: =INDEX($Y$14:$AB$21,MATCH(AD20,$AB$14:$AB$21,0),3) -> 7.5
A21: =A9 -> DONOVAN | B21: =B9 -> 18 | C21: =IF($B$21>=C18,"●","")&(IF($B$21-18>=C18,"●","")) -> ● | D21: =IF($B$21>=D18,"●","")&(IF($B$21-18>=D18,"●","")) -> ● | E21: =IF($B$21>=E18,"●","")&(IF($B$21-18>=E18,"●","")) -> ● | F21: =IF($B$21>=F18,"●","")&(IF($B$21-18>=F18,"●","")) -> ● | G21: =IF($B$21>=G18,"●","")&(IF($B$21-18>=G18,"●","")) -> ● | H21: =IF($B$21>=H18,"●","")&(IF($B$21-18>=H18,"●","")) -> ● | I21: =IF($B$21>=I18,"●","")&(IF($B$21-18>=I18,"●","")) -> ● | J21: =IF($B$21>=J18,"●","")&(IF($B$21-18>=J18,"●","")) -> ● | ... T21: =IF($B$21>=T18,"●","")&(IF($B$21-18>=T18,"●","")) -> ● | Y21: =Y11 -> STONES | Z21: =Z11 -> 49 | AA21: =AG11 -> 24 | AB21: =RANK(Z21,$Z$14:$Z$21,0)+COUNTIF($Z$14:Z21,Z21)-1 -> 1 | AD21: 8 | AE21: =INDEX($Y$14:$AB$21,MATCH(AD21,$AB$14:$AB$21,0),1) -> LAING | AF21: =INDEX($Y$14:$AB$21,MATCH(AD21,$AB$14:$AB$21,0),2) -> 16 | AG21: =INDEX($Y$14:$AB$21,MATCH(AD21,$AB$14:$AB$21,0),3) -> 3
A22: =A10 -> FINDLAY | B22: =B10 -> 18 | C22: =IF($B$22>=C18,"●","")&(IF($B$22-18>=C18,"●","")) -> ● | D22: =IF($B$22>=D18,"●","")&(IF($B$22-18>=D18,"●","")) -> ● | E22: =IF($B$22>=E18,"●","")&(IF($B$22-18>=E18,"●","")) -> ● | F22: =IF($B$22>=F18,"●","")&(IF($B$22-18>=F18,"●","")) -> ● | G22: =IF($B$22>=G18,"●","")&(IF($B$22-18>=G18,"●","")) -> ● | H22: =IF($B$22>=H18,"●","")&(IF($B$22-18>=H18,"●","")) -> ● | I22: =IF($B$22>=I18,"●","")&(IF($B$22-18>=I18,"●","")) -> ● | J22: =IF($B$22>=J18,"●","")&(IF($B$22-18>=J18,"●","")) -> ● | ... T22: =IF($B$22>=T18,"●","")&(IF($B$22-18>=T18,"●","")) -> ●
A23: =A11 -> HOLLANDS | B23: =B11 -> 18 | C23: =IF($B$23>=C18,"●","")&(IF($B$23-18>=C18,"●","")) -> ● | D23: =IF($B$23>=D18,"●","")&(IF($B$23-18>=D18,"●","")) -> ● | E23: =IF($B$23>=E18,"●","")&(IF($B$23-18>=E18,"●","")) -> ● | F23: =IF($B$23>=F18,"●","")&(IF($B$23-18>=F18,"●","")) -> ● | G23: =IF($B$23>=G18,"●","")&(IF($B$23-18>=G18,"●","")) -> ● | H23: =IF($B$23>=H18,"●","")&(IF($B$23-18>=H18,"●","")) -> ● | I23: =IF($B$23>=I18,"●","")&(IF($B$23-18>=I18,"●","")) -> ● | J23: =IF($B$23>=J18,"●","")&(IF($B$23-18>=J18,"●","")) -> ● | ... T23: =IF($B$23>=T18,"●","")&(IF($B$23-18>=T18,"●","")) -> ●
A24: =A12 -> LAING | B24: =B12 -> 18 | C24: =IF($B$24>=C18,"●","")&(IF($B$24-18>=C18,"●","")) -> ● | D24: =IF($B$24>=D18,"●","")&(IF($B$24-18>=D18,"●","")) -> ● | E24: =IF($B$24>=E18,"●","")&(IF($B$24-18>=E18,"●","")) -> ● | F24: =IF($B$24>=F18,"●","")&(IF($B$24-18>=F18,"●","")) -> ● | G24: =IF($B$24>=G18,"●","")&(IF($B$24-18>=G18,"●","")) -> ● | H24: =IF($B$24>=H18,"●","")&(IF($B$24-18>=H18,"●","")) -> ● | I24: =IF($B$24>=I18,"●","")&(IF($B$24-18>=I18,"●","")) -> ● | J24: =IF($B$24>=J18,"●","")&(IF($B$24-18>=J18,"●","")) -> ● | ... T24: =IF($B$24>=T18,"●","")&(IF($B$24-18>=T18,"●","")) -> ●
A25: =A13 -> REILLY | B25: =B13 -> 18 | C25: =IF($B$25>=C18,"●","")&(IF($B$25-18>=C18,"●","")) -> ● | D25: =IF($B$25>=D18,"●","")&(IF($B$25-18>=D18,"●","")) -> ● | E25: =IF($B$25>=E18,"●","")&(IF($B$25-18>=E18,"●","")) -> ● | F25: =IF($B$25>=F18,"●","")&(IF($B$25-18>=F18,"●","")) -> ● | G25: =IF($B$25>=G18,"●","")&(IF($B$25-18>=G18,"●","")) -> ● | H25: =IF($B$25>=H18,"●","")&(IF($B$25-18>=H18,"●","")) -> ● | I25: =IF($B$25>=I18,"●","")&(IF($B$25-18>=I18,"●","")) -> ● | J25: =IF($B$25>=J18,"●","")&(IF($B$25-18>=J18,"●","")) -> ● | ... T25: =IF($B$25>=T18,"●","")&(IF($B$25-18>=T18,"●","")) -> ●
A26: =A14 -> STONES | B26: =B14 -> 18 | C26: =IF($B$26>=C18,"●","")&(IF($B$26-18>=C18,"●","")) -> ● | D26: =IF($B$26>=D18,"●","")&(IF($B$26-18>=D18,"●","")) -> ● | E26: =IF($B$26>=E18,"●","")&(IF($B$26-18>=E18,"●","")) -> ● | F26: =IF($B$26>=F18,"●","")&(IF($B$26-18>=F18,"●","")) -> ● | G26: =IF($B$26>=G18,"●","")&(IF($B$26-18>=G18,"●","")) -> ● | H26: =IF($B$26>=H18,"●","")&(IF($B$26-18>=H18,"●","")) -> ● | I26: =IF($B$26>=I18,"●","")&(IF($B$26-18>=I18,"●","")) -> ● | J26: =IF($B$26>=J18,"●","")&(IF($B$26-18>=J18,"●","")) -> ● | ... T26: =IF($B$26>=T18,"●","")&(IF($B$26-18>=T18,"●","")) -> ●
C28: =C16 -> 1 | D28: =D16 -> 2 | E28: =E16 -> 3 | F28: =F16 -> 4 | G28: =G16 -> 5 | H28: =H16 -> 6 | I28: =I16 -> 7 | J28: =J16 -> 8 | ... T28: =T16 -> 18 | U28: TOTAL | V28: NET SCORE
C29: =C17 -> 4 | D29: =D17 -> 3 | E29: =E17 -> 4 | F29: =F17 -> 4 | G29: =G17 -> 4 | H29: =H17 -> 4 | I29: =I17 -> 4 | J29: =J17 -> 3 | ... T29: =T17 -> 4
C30: =C18 -> 9 | D30: =D18 -> 13 | E30: =E18 -> 5 | F30: =F18 -> 1 | G30: =G18 -> 11 | H30: =H18 -> 15 | I30: =I18 -> 7 | J30: =J18 -> 17 | ... T30: =T18 -> 2
A31: =A19 -> BELLIS | B31: =B19 -> 18 | C31: =C7+IF(C19="●",-1)+IF(C19="●●",-2) -> 4 | D31: =D7+IF(D19="●",-1)+IF(D19="●●",-2) -> 4 | E31: =E7+IF(E19="●",-1)+IF(E19="●●",-2) -> 4 | F31: =F7+IF(F19="●",-1)+IF(F19="●●",-2) -> 4 | G31: =G7+IF(G19="●",-1)+IF(G19="●●",-2) -> 4 | H31: =H7+IF(H19="●",-1)+IF(H19="●●",-2) -> 4 | I31: =I7+IF(I19="●",-1)+IF(I19="●●",-2) -> 4 | J31: =J7+IF(J19="●",-1)+IF(J19="●●",-2) -> 4 | ... T31: =T7+IF(T19="●",-1)+IF(T19="●●",-2) -> 4
A32: =A20 -> DEY | B32: =B20 -> 18 | C32: =C8+IF(C20="●",-1)+IF(C20="●●",-2) -> 4 | D32: =D8+IF(D20="●",-1)+IF(D20="●●",-2) -> 8 | E32: =E8+IF(E20="●",-1)+IF(E20="●●",-2) -> 5 | F32: =F8+IF(F20="●",-1)+IF(F20="●●",-2) -> 8 | G32: =G8+IF(G20="●",-1)+IF(G20="●●",-2) -> 5 | H32: =H8+IF(H20="●",-1)+IF(H20="●●",-2) -> 8 | I32: =I8+IF(I20="●",-1)+IF(I20="●●",-2) -> 5 | J32: =J8+IF(J20="●",-1)+IF(J20="●●",-2) -> 8 | ... T32: =T8+IF(T20="●",-1)+IF(T20="●●",-2) -> -1
A33: =A21 -> DONOVAN | B33: =B21 -> 18 | C33: =C9+IF(C21="●",-1)+IF(C21="●●",-2) -> 4 | D33: =D9+IF(D21="●",-1)+IF(D21="●●",-2) -> 8 | E33: =E9+IF(E21="●",-1)+IF(E21="●●",-2) -> 5 | F33: =F9+IF(F21="●",-1)+IF(F21="●●",-2) -> 8 | G33: =G9+IF(G21="●",-1)+IF(G21="●●",-2) -> 5 | H33: =H9+IF(H21="●",-1)+IF(H21="●●",-2) -> 8 | I33: =I9+IF(I21="●",-1)+IF(I21="●●",-2) -> 5 | J33: =J9+IF(J21="●",-1)+IF(J21="●●",-2) -> 8 | ... T33: =T9+IF(T21="●",-1)+IF(T21="●●",-2) -> -1
A34: =A22 -> FINDLAY | B34: =B22 -> 18 | C34: =C10+IF(C22="●",-1)+IF(C22="●●",-2) -> 4 | D34: =D10+IF(D22="●",-1)+IF(D22="●●",-2) -> 3 | E34: =E10+IF(E22="●",-1)+IF(E22="●●",-2) -> 5 | F34: =F10+IF(F22="●",-1)+IF(F22="●●",-2) -> 3 | G34: =G10+IF(G22="●",-1)+IF(G22="●●",-2) -> 5 | H34: =H10+IF(H22="●",-1)+IF(H22="●●",-2) -> 8 | I34: =I10+IF(I22="●",-1)+IF(I22="●●",-2) -> 5 | J34: =J10+IF(J22="●",-1)+IF(J22="●●",-2) -> 3 | ... T34: =T10+IF(T22="●",-1)+IF(T22="●●",-2) -> -1
A35: =A23 -> HOLLANDS | B35: =B23 -> 18 | C35: =C11+IF(C23="●",-1)+IF(C23="●●",-2) -> 5 | D35: =D11+IF(D23="●",-1)+IF(D23="●●",-2) -> 3 | E35: =E11+IF(E23="●",-1)+IF(E23="●●",-2) -> 5 | F35: =F11+IF(F23="●",-1)+IF(F23="●●",-2) -> 8 | G35: =G11+IF(G23="●",-1)+IF(G23="●●",-2) -> 5 | H35: =H11+IF(H23="●",-1)+IF(H23="●●",-2) -> 8 | I35: =I11+IF(I23="●",-1)+IF(I23="●●",-2) -> 5 | J35: =J11+IF(J23="●",-1)+IF(J23="●●",-2) -> 8 | ... T35: =T11+IF(T23="●",-1)+IF(T23="●●",-2) -> -1
A36: =A24 -> LAING | B36: =B24 -> 18 | C36: =C12+IF(C24="●",-1)+IF(C24="●●",-2) -> 5 | D36: =D12+IF(D24="●",-1)+IF(D24="●●",-2) -> 8 | E36: =E12+IF(E24="●",-1)+IF(E24="●●",-2) -> 5 | F36: =F12+IF(F24="●",-1)+IF(F24="●●",-2) -> 8 | G36: =G12+IF(G24="●",-1)+IF(G24="●●",-2) -> 5 | H36: =H12+IF(H24="●",-1)+IF(H24="●●",-2) -> 8 | I36: =I12+IF(I24="●",-1)+IF(I24="●●",-2) -> 5 | J36: =J12+IF(J24="●",-1)+IF(J24="●●",-2) -> 8 | ... T36: =T12+IF(T24="●",-1)+IF(T24="●●",-2) -> -1
A37: =A25 -> REILLY | B37: =B25 -> 18 | C37: =C13+IF(C25="●",-1)+IF(C25="●●",-2) -> 5 | D37: =D13+IF(D25="●",-1)+IF(D25="●●",-2) -> -1 | E37: =E13+IF(E25="●",-1)+IF(E25="●●",-2) -> -1 | F37: =F13+IF(F25="●",-1)+IF(F25="●●",-2) -> -1 | G37: =G13+IF(G25="●",-1)+IF(G25="●●",-2) -> -1 | H37: =H13+IF(H25="●",-1)+IF(H25="●●",-2) -> -1 | I37: =I13+IF(I25="●",-1)+IF(I25="●●",-2) -> -1 | J37: =J13+IF(J25="●",-1)+IF(J25="●●",-2) -> -1 | ... T37: =T13+IF(T25="●",-1)+IF(T25="●●",-2) -> -1
A38: =A26 -> STONES | B38: =B26 -> 18 | C38: =C14+IF(C26="●",-1)+IF(C26="●●",-2) -> 5 | D38: =D14+IF(D26="●",-1)+IF(D26="●●",-2) -> 3 | E38: =E14+IF(E26="●",-1)+IF(E26="●●",-2) -> 3 | F38: =F14+IF(F26="●",-1)+IF(F26="●●",-2) -> 6 | G38: =G14+IF(G26="●",-1)+IF(G26="●●",-2) -> 3 | H38: =H14+IF(H26="●",-1)+IF(H26="●●",-2) -> 3 | I38: =I14+IF(I26="●",-1)+IF(I26="●●",-2) -> 3 | J38: =J14+IF(J26="●",-1)+IF(J26="●●",-2) -> 3 | ... T38: =T14+IF(T26="●",-1)+IF(T26="●●",-2) -> 3
C40: =C28 -> 1 | D40: =D28 -> 2 | E40: =E28 -> 3 | F40: =F28 -> 4 | G40: =G28 -> 5 | H40: =H28 -> 6 | I40: =I28 -> 7 | J40: =J28 -> 8 | ... T40: =T28 -> 18 | U40: TOTAL | V40: STABLEFORD
C41: =C29 -> 4 | D41: =D29 -> 3 | E41: =E29 -> 4 | F41: =F29 -> 4 | G41: =G29 -> 4 | H41: =H29 -> 4 | I41: =I29 -> 4 | J41: =J29 -> 3 | ... T41: =T29 -> 4
C42: =C30 -> 9 | D42: =D30 -> 13 | E42: =E30 -> 5 | F42: =F30 -> 1 | G42: =G30 -> 11 | H42: =H30 -> 15 | I42: =I30 -> 7 | J42: =J30 -> 17 | ... T42: =T30 -> 2
A43: =A31 -> BELLIS | B43: =B7 -> 18 | C43: =C31-C29 -> 0 | D43: =D31-D29 -> 1 | E43: =E31-E29 -> 0 | F43: =F31-F29 -> 0 | G43: =G31-G29 -> 0 | H43: =H31-H29 -> 0 | I43: =I31-I29 -> 0 | J43: =J31-J29 -> 1 | ... T43: =T31-T29 -> 0
A44: =A32 -> DEY | B44: =B8 -> 18 | C44: =C32-C29 -> 0 | D44: =D32-D29 -> 5 | E44: =E32-E29 -> 1 | F44: =F32-F29 -> 4 | G44: =G32-G29 -> 1 | H44: =H32-H29 -> 4 | I44: =I32-I29 -> 1 | J44: =J32-J29 -> 5 | ... T44: =T32-T29 -> -5
...

Sheet Round2
B3: TOURNAMENT STANDINGS
A6: RANK | B6: PLAYER | C6: SCORE | D6: POINTS
A7: ='RND 1 STBL'!AD14 -> 1 | B7: ='RND 2 MP'!AE14 -> FINDLAY | C7: ='RND 2 MP'!AF14 -> 39 | D7: ='RND 2 MP'!AG14 -> 22.5
A8: ='RND 1 STBL'!AD15 -> 2 | B8: ='RND 2 MP'!AE15 -> HOLLANDS | C8: ='RND 2 MP'!AF15 -> 39 | D8: ='RND 2 MP'!AG15 -> 22.5
A9: ='RND 1 STBL'!AD16 -> 3 | B9: ='RND 2 MP'!AE16 -> DONOVAN | C9: ='RND 2 MP'!AF16 -> 32 | D9: ='RND 2 MP'!AG16 -> 18
A10: ='RND 1 STBL'!AD17 -> 4 | B10: ='RND 2 MP'!AE17 -> LAING | C10: ='RND 2 MP'!AF17 -> 21 | D10: ='RND 2 MP'!AG17 -> 15
A11: ='RND 1 STBL'!AD18 -> 5 | B11: ='RND 2 MP'!AE18 -> REILLY | C11: ='RND 2 MP'!AF18 -> 12 | D11: ='RND 2 MP'!AG18 -> 12
A12: ='RND 1 STBL'!AD19 -> 6 | B12: ='RND 2 MP'!AE19 -> DEY | C12: ='RND 2 MP'!AF19 -> 10 | D12: ='RND 2 MP'!AG19 -> 7.5
A13: ='RND 1 STBL'!AD20 -> 7 | B13: ='RND 2 MP'!AE20 -> STONES | C13: ='RND 2 MP'!AF20 -> 10 | D13: ='RND 2 MP'!AG20 -> 7.5
A14: ='RND 1 STBL'!AD21 -> 8 | B14: ='RND 2 MP'!AE21 -> BELLIS | C14: ='RND 2 MP'!AF21 -> 5 | D14: ='RND 2 MP'!AG21 -> 3
A21: Round 2 - Strokes
A22: PLAYERS | B22: HCP | D22: HOLE | E22: 1 | F22: 2 | G22: 3 | H22: 4 | I22: 5 | J22: 6 | K22: 7 | L22: 8 | M22: 9 | N22: 10 | O22: 11 | P22: 12 | Q22: 13 | R22: 14 | S22: 15 | T22: 16 | U22: 17 | V22: 18 | W22: TOTAL
D23: PAR | E23: ='RND 2 MP'!C5 -> 4 | F23: ='RND 2 MP'!D5 -> 3 | G23: ='RND 2 MP'!E5 -> 4 | H23: ='RND 2 MP'!F5 -> 4 | I23: ='RND 2 MP'!G5 -> 4 | J23: ='RND 2 MP'!H5 -> 5 | K23: ='RND 2 MP'!I5 -> 3 | L23: ='RND 2 MP'!J5 -> 4 | ... V23: ='RND 2 MP'!T5 -> 4
D24: S.I | E24: ='RND 2 MP'!C6 -> 16 | F24: ='RND 2 MP'!D6 -> 8 | G24: ='RND 2 MP'!E6 -> 2 | H24: ='RND 2 MP'!F6 -> 18 | I24: ='RND 2 MP'!G6 -> 4 | J24: ='RND 2 MP'!H6 -> 12 | K24: ='RND 2 MP'!I6 -> 6 | L24: ='RND 2 MP'!J6 -> 10 | ... V24: ='RND 2 MP'!T6 -> 9
A26: ='RND 1 STBL'!A7 -> BELLIS | B26: ='RND 2 MP'!B7 -> 18 | E26: ='RND 2 MP'!C7 -> 8 | F26: ='RND 2 MP'!D7 -> 2 | G26: ='RND 2 MP'!E7 -> 8 | H26: ='RND 2 MP'!F7 -> 8 | I26: ='RND 2 MP'!G7 -> 8 | J26: ='RND 2 MP'!H7 -> 8 | K26: ='RND 2 MP'!I7 -> 8 | L26: ='RND 2 MP'!J7 -> 8 | ... W26: ='RND 2 MP'!U7 -> 133
A27: ='RND 1 STBL'!A8 -> DEY | B27: ='RND 2 MP'!B8 -> 18 | E27: ='RND 2 MP'!C8 -> 7 | F27: ='RND 2 MP'!D8 -> 7 | G27: ='RND 2 MP'!E8 -> 7 | H27: ='RND 2 MP'!F8 -> 7 | I27: ='RND 2 MP'!G8 -> 7 | J27: ='RND 2 MP'!H8 -> 1 | K27: ='RND 2 MP'!I8 -> 1 | L27: ='RND 2 MP'!J8 -> 1 | ... W27: ='RND 2 MP'!U8 -> 128
A28: ='RND 1 STBL'!A9 -> DONOVAN | B28: ='RND 2 MP'!B9 -> 18 | E28: ='RND 2 MP'!C9 -> 4 | F28: ='RND 2 MP'!D9 -> 9 | G28: ='RND 2 MP'!E9 -> 3 | H28: ='RND 2 MP'!F9 -> 2 | I28: ='RND 2 MP'!G9 -> 4 | J28: ='RND 2 MP'!H9 -> 4 | K28: ='RND 2 MP'!I9 -> 4 | L28: ='RND 2 MP'!J9 -> 4 | ... W28: ='RND 2 MP'!U9 -> 78
A29: ='RND 1 STBL'!A10 -> FINDLAY | B29: ='RND 2 MP'!B10 -> 18 | E29: ='RND 2 MP'!C10 -> 2 | F29: ='RND 2 MP'!D10 -> 3 | G29: ='RND 2 MP'!E10 -> 6 | H29: ='RND 2 MP'!F10 -> 3 | I29: ='RND 2 MP'!G10 -> 2 | J29: ='RND 2 MP'!H10 -> 2 | K29: ='RND 2 MP'!I10 -> 2 | L29: ='RND 2 MP'!J10 -> 1 | ... W29: ='RND 2 MP'!U10 -> 60
A30: ='RND 1 STBL'!A11 -> HOLLANDS | B30: ='RND 2 MP'!B11 -> 18 | E30: ='RND 2 MP'!C11 -> 2 | F30: ='RND 2 MP'!D11 -> 3 | G30: ='RND 2 MP'!E11 -> 6 | H30: ='RND 2 MP'!F11 -> 3 | I30: ='RND 2 MP'!G11 -> 2 | J30: ='RND 2 MP'!H11 -> 2 | K30: ='RND 2 MP'!I11 -> 2 | L30: ='RND 2 MP'!J11 -> 1 | ... W30: ='RND 2 MP'!U11 -> 60
A31: ='RND 1 STBL'!A12 -> LAING | B31: ='RND 2 MP'!B12 -> 18 | E31: ='RND 2 MP'!C12 -> 7 | F31: ='RND 2 MP'!D12 -> 6 | G31: ='RND 2 MP'!E12 -> 4 | H31: ='RND 2 MP'!F12 -> 4 | I31: ='RND 2 MP'!G12 -> 3 | J31: ='RND 2 MP'!H12 -> 4 | K31: ='RND 2 MP'!I12 -> 7 | L31: ='RND 2 MP'!J12 -> 2 | ... W31: ='RND 2 MP'!U12 -> 90
A32: ='RND 1 STBL'!A13 -> REILLY | B32: ='RND 2 MP'!B13 -> 18 | E32: ='RND 2 MP'!C13 -> 7 | F32: ='RND 2 MP'!D13 -> 5 | G32: ='RND 2 MP'!E13 -> 7 | H32: ='RND 2 MP'!F13 -> 7 | I32: ='RND 2 MP'!G13 -> 7 | J32: ='RND 2 MP'!H13 -> 1 | K32: ='RND 2 MP'!I13 -> 1 | L32: ='RND 2 MP'!J13 -> 7 | ... W32: ='RND 2 MP'!U13 -> 109
A33: ='RND 1 STBL'!A14 -> STONES | B33: ='RND 2 MP'!B14 -> 18 | E33: ='RND 2 MP'!C14 -> 7 | F33: ='RND 2 MP'!D14 -> 4 | G33: ='RND 2 MP'!E14 -> 7 | H33: ='RND 2 MP'!F14 -> 7 | I33: ='RND 2 MP'!G14 -> 7 | J33: ='RND 2 MP'!H14 -> 7 | K33: ='RND 2 MP'!I14 -> 7 | L33: ='RND 2 MP'!J14 -> 7 | ... W33: ='RND 2 MP'!U14 -> 114
A37: Round 2 - Net Scores
A38: PLAYERS | B38: HCP | D38: HOLE | E38: 1 | F38: 2 | G38: 3 | H38: 4 | I38: 5 | J38: 6 | K38: 7 | L38: 8 | M38: 9 | N38: 10 | O38: 11 | P38: 12 | Q38: 13 | R38: 14 | S38: 15 | T38: 16 | U38: 17 | V38: 18 | W38: TOTAL
D39: PAR | E39: =E23 -> 4 | F39: =F23 -> 3 | G39: =G23 -> 4 | H39: =H23 -> 4 | I39: =I23 -> 4 | J39: =J23 -> 5 | K39: =K23 -> 3 | L39: =L23 -> 4 | ... V39: =V23 -> 4
D40: S.I | E40: =E24 -> 16 | F40: =F24 -> 8 | G40: =G24 -> 2 | H40: =H24 -> 18 | I40: =I24 -> 4 | J40: =J24 -> 12 | K40: =K24 -> 6 | L40: =L24 -> 10 | ... V40: =V24 -> 9
A42: =A26 -> BELLIS | B42: =B26 -> 18 | E42: ='RND 2 MP'!C31 -> 7 | F42: ='RND 2 MP'!D31 -> 1 | G42: ='RND 2 MP'!E31 -> 7 | H42: ='RND 2 MP'!F31 -> 7 | I42: ='RND 2 MP'!G31 -> 7 | J42: ='RND 2 MP'!H31 -> 7 | K42: ='RND 2 MP'!I31 -> 7 | L42: ='RND 2 MP'!J31 -> 7 | ... W42: ='RND 2 MP'!U31 -> 115
A43: =A27 -> DEY | B43: =B27 -> 18 | E43: ='RND 2 MP'!C32 -> 6 | F43: ='RND 2 MP'!D32 -> 6 | G43: ='RND 2 MP'!E32 -> 6 | H43: ='RND 2 MP'!F32 -> 6 | I43: ='RND 2 MP'!G32 -> 6 | J43: ='RND 2 MP'!H32 -> 0 | K43: ='RND 2 MP'!I32 -> 0 | L43: ='RND 2 MP'!J32 -> 0 | ... W43: ='RND 2 MP'!U32 -> 110
A44: =A28 -> DONOVAN | B44: =B28 -> 18 | E44: ='RND 2 MP'!C33 -> 3 | F44: ='RND 2 MP'!D33 -> 8 | G44: ='RND 2 MP'!E33 -> 2 | H44: ='RND 2 MP'!F33 -> 1 | I44: ='RND 2 MP'!G33 -> 3 | J44: ='RND 2 MP'!H33 -> 3 | K44: ='RND 2 MP'!I33 -> 3 | L44: ='RND 2 MP'!J33 -> 3 | ... W44: ='RND 2 MP'!U33 -> 60
A45: =A29 -> FINDLAY | B45: =B29 -> 18 | E45: ='RND 2 MP'!C34 -> 1 | F45: ='RND 2 MP'!D34 -> 2 | G45: ='RND 2 MP'!E34 -> 5 | H45: ='RND 2 MP'!F34 -> 2 | I45: ='RND 2 MP'!G34 -> 1 | J45: ='RND 2 MP'!H34 -> 1 | K45: ='RND 2 MP'!I34 -> 1 | L45: ='RND 2 MP'!J34 -> 0 | ... W45: ='RND 2 MP'!U34 -> 42
A46: =A30 -> HOLLANDS | B46: =B30 -> 18 | E46: ='RND 2 MP'!C35 -> 1 | F46: ='RND 2 MP'!D35 -> 2 | G46: ='RND 2 MP'!E35 -> 5 | H46: ='RND 2 MP'!F35 -> 2 | I46: ='RND 2 MP'!G35 -> 1 | J46: ='RND 2 MP'!H35 -> 1 | K46: ='RND 2 MP'!I35 -> 1 | L46: ='RND 2 MP'!J35 -> 0 | ... W46: ='RND 2 MP'!U35 -> 42
A47: =A31 -> LAING | B47: =B31 -> 18 | E47: ='RND 2 MP'!C36 -> 6 | F47: ='RND 2 MP'!D36 -> 5 | G47: ='RND 2 MP'!E36 -> 3 | H47: ='RND 2 MP'!F36 -> 3 | I47: ='RND 2 MP'!G36 -> 2 | J47: ='RND 2 MP'!H36 -> 3 | K47: ='RND 2 MP'!I36 -> 6 | L47: ='RND 2 MP'!J36 -> 1 | ... W47: ='RND 2 MP'!U36 -> 72
A48: =A32 -> REILLY | B48: =B32 -> 18 | E48: ='RND 2 MP'!C37 -> 6 | F48: ='RND 2 MP'!D37 -> 4 | G48: ='RND 2 MP'!E37 -> 6 | H48: ='RND 2 MP'!F37 -> 6 | I48: ='RND 2 MP'!G37 -> 6 | J48: ='RND 2 MP'!H37 -> 0 | K48: ='RND 2 MP'!I37 -> 0 | L48: ='RND 2 MP'!J37 -> 6 | ... W48: ='RND 2 MP'!U37 -> 91
A49: =A33 -> STONES | B49: =B33 -> 18 | E49: ='RND 2 MP'!C38 -> 6 | F49: ='RND 2 MP'!D38 -> 3 | G49: ='RND 2 MP'!E38 -> 6 | H49: ='RND 2 MP'!F38 -> 6 | I49: ='RND 2 MP'!G38 -> 6 | J49: ='RND 2 MP'!H38 -> 6 | K49: ='RND 2 MP'!I38 -> 6 | L49: ='RND 2 MP'!J38 -> 6 | ... W49: ='RND 2 MP'!U38 -> 96
A53: Round 2 - Matchplay Order
A54: PLAYERS | B54: MP Points | D54: HOLE | E54: 1 | F54: 2 | G54: 3 | H54: 4 | I54: 5 | J54: 6 | K54: 7 | L54: 8 | M54: 9 | N54: 10 | O54: 11 | P54: 12 | Q54: 13 | R54: 14 | S54: 15 | T54: 16 | U54: 17 | V54: 18 | W54: TOTAL
D55: PAR | E55: =E39 -> 4 | F55: =F39 -> 3 | G55: =G39 -> 4 | H55: =H39 -> 4 | I55: =I39 -> 4 | J55: =J39 -> 5 | K55: =K39 -> 3 | L55: =L39 -> 4 | ... V55: =V39 -> 4
D56: S.I | E56: =E40 -> 16 | F56: =F40 -> 8 | G56: =G40 -> 2 | H56: =H40 -> 18 | I56: =I40 -> 4 | J56: =J40 -> 12 | K56: =K40 -> 6 | L56: =L40 -> 10 | ... V56: =V40 -> 9
A58: =A42 -> BELLIS | B58: ='RND 2 MP'!U56 -> 5 | E58: {=IFERROR( INDEX($A$99:$A$106, MATCH( LARGE( INDEX($E$99:$V$106, 0, COLUMN()-4) + ROW($A$99:$A$106)/1000, ROW(A1) ), INDEX($E$99:$V$106, 0, COLUMN()-4) + ROW($A$99:$A$106)/1000, 0) ), "")} -> HOLLANDS | F58: {=IFERROR( INDEX($A$99:$A$106, MATCH( LARGE( INDEX($E$99:$V$106, 0, COLUMN()-4) + ROW($A$99:$A$106)/1000, ROW(B1) ), INDEX($E$99:$V$106, 0, COLUMN()-4) + ROW($A$99:$A$106)/1000, 0) ), "")} -> BELLIS | G58: {=IFERROR( INDEX($A$99:$A$106, MATCH( LARGE( INDEX($E$99:$V$106, 0, COLUMN()-4) + ROW($A$99:$A$106)/1000, ROW(C1) ), INDEX($E$99:$V$106, 0, COLUMN()-4) + ROW($A$99:$A$106)/1000, 0) ), "")} -> DONOVAN | H58: {=IFERROR( INDEX($A$99:$A$106, MATCH( LARGE( INDEX($E$99:$V$106, 0, COLUMN()-4) + ROW($A$99:$A$106)/1000, ROW(D1) ), INDEX($E$99:$V$106, 0, COLUMN()-4) + ROW($A$99:$A$106)/1000, 0) ), "")} -> DONOVAN | I58: {=IFERROR( INDEX($A$99:$A$106, MATCH( LARGE( INDEX($E$99:$V$106, 0, COLUMN()-4) + ROW($A$99:$A$106)/1000, ROW(E1) ), INDEX($E$99:$V$106, 0, COLUMN()-4) + ROW($A$99:$A$106)/1000, 0) ), "")} -> HOLLANDS | J58: {=IFERROR( INDEX($A$99:$A$106, MATCH( LARGE( INDEX($E$99:$V$106, 0, COLUMN()-4) + ROW($A$99:$A$106)/1000, ROW(F1) ), INDEX($E$99:$V$106, 0, COLUMN()-4) + ROW($A$99:$A$106)/1000, 0) ), "")} -> REILLY | K58: {=IFERROR( INDEX($A$99:$A$106, MATCH( LARGE( INDEX($E$99:$V$106, 0, COLUMN()-4) + ROW($A$99:$A$106)/1000, ROW(G1) ), INDEX($E$99:$V$106, 0, COLUMN()-4) + ROW($A$99:$A$106)/1000, 0) ), "")} -> REILLY | L58: {=IFERROR( INDEX($A$99:$A$106, MATCH( LARGE( INDEX($E$99:$V$106, 0, COLUMN()-4) + ROW($A$99:$A$106)/1000, ROW(H1) ), INDEX($E$99:$V$106, 0, COLUMN()-4) + ROW($A$99:$A$106)/1000, 0) ), "")} -> HOLLANDS | ... V58: {=IFERROR( INDEX($A$99:$A$106, MATCH( LARGE( INDEX($E$99:$V$106, 0, COLUMN()-4) + ROW($A$99:$A$106)/1000, ROW(R1) ), INDEX($E$99:$V$106, 0, COLUMN()-4) + ROW($A$99:$A$106)/1000, 0) ), "")} -> STONES
A59: =A43 -> DEY | B59: ='RND 2 MP'!U57 -> 10 | E59: {=IFERROR( INDEX($A$99:$A$106, MATCH( LARGE( INDEX($E$99:$V$106, 0, COLUMN()-4) + ROW($A$99:$A$106)/1000, ROW(A2) ), INDEX($E$99:$V$106, 0, COLUMN()-4) + ROW($A$99:$A$106)/1000, 0) ), "")} -> FINDLAY | F59: {=IFERROR( INDEX($A$99:$A$106, MATCH( LARGE( INDEX($E$99:$V$106, 0, COLUMN()-4) + ROW($A$99:$A$106)/1000, ROW(B2) ), INDEX($E$99:$V$106, 0, COLUMN()-4) + ROW($A$99:$A$106)/1000, 0) ), "")} -> HOLLANDS | G59: {=IFERROR( INDEX($A$99:$A$106, MATCH( LARGE( INDEX($E$99:$V$106, 0, COLUMN()-4) + ROW($A$99:$A$106)/1000, ROW(C2) ), INDEX($E$99:$V$106, 0, COLUMN()-4) + ROW($A$99:$A$106)/1000, 0) ), "")} -> LAING | H59: {=IFERROR( INDEX($A$99:$A$106, MATCH( LARGE( INDEX($E$99:$V$106, 0, COLUMN()-4) + ROW($A$99:$A$106)/1000, ROW(D2) ), INDEX($E$99:$V$106, 0, COLUMN()-4) + ROW($A$99:$A$106)/1000, 0) ), "")} -> HOLLANDS | I59: {=IFERROR( INDEX($A$99:$A$106, MATCH( LARGE( INDEX($E$99:$V$106, 0, COLUMN()-4) + ROW($A$99:$A$106)/1000, ROW(E2) ), INDEX($E$99:$V$106, 0, COLUMN()-4) + ROW($A$99:$A$106)/1000, 0) ), "")} -> FINDLAY | J59: {=IFERROR( INDEX($A$99:$A$106, MATCH( LARGE( INDEX($E$99:$V$106, 0, COLUMN()-4) + ROW($A$99:$A$106)/1000, ROW(F2) ), INDEX($E$99:$V$106, 0, COLUMN()-4) + ROW($A$99:$A$106)/1000, 0) ), "")} -> DEY | K59: {=IFERROR( INDEX($A$99:$A$106, MATCH( LARGE( INDEX($E$99:$V$106, 0, COLUMN()-4) + ROW($A$99:$A$106)/1000, ROW(G2) ), INDEX($E$99:$V$106, 0, COLUMN()-4) + ROW($A$99:$A$106)/1000, 0) ), "")} -> DEY | L59: {=IFERROR( INDEX($A$99:$A$106, MATCH( LARGE( INDEX($E$99:$V$106, 0, COLUMN()-4) + ROW($A$99:$A$106)/1000, ROW(H2) ), INDEX($E$99:$V$106, 0, COLUMN()-4) + ROW($A$99:$A$106)/1000, 0) ), "")} -> FINDLAY | ... V59: {=IFERROR( INDEX($A$99:$A$106, MATCH( LARGE( INDEX($E$99:$V$106, 0, COLUMN()-4) + ROW($A$99:$A$106)/1000, ROW(R2) ), INDEX($E$99:$V$106, 0, COLUMN()-4) + ROW($A$99:$A$106)/1000, 0) ), "")} -> REILLY
...

Sheet RND 2 MP
A1: ROUND 2 SCORECARD & POINTS Blue Canyon | Y1: TOURNAMENT RANKER
A4: PLAYERS | B4: HCP | C4: 1 | D4: 2 | E4: 3 | F4: 4 | G4: 5 | H4: 6 | I4: 7 | J4: 8 | K4: 9 | L4: 10 | M4: 11 | N4: 12 | O4: 13 | P4: 14 | Q4: 15 | R4: 16 | S4: 17 | T4: 18 | U4: TOTAL | V4: SCORECARD | Y4: =A7 -> BELLIS | Z4: =U56 -> 5 | AA4: =RANK(Z4,$Z$4:$Z$11,0) -> 8 | AD4: =IF(AA4=1,24,0)+(IF(AA4=2,21,0))+(IF(AA4=3,18,0))+(IF(AA4=4,15,0))+(IF(AA4=5,12,0))+(IF(AA4=6,9,0))+(IF(AA4=7,6,0))+(IF(AA4=8,3,0)) -> 3 | AE4: =COUNTIF($AD$4:$AD$11,AD4) -> 1 | AF4: =SUMIF($AD$4:$AD$11,AD4) -> 3 | AG4: =IF(AE4=3,AF4/3-3,0)+IF(AE4=2,AF4/2-1.5,0)+IF(AE4=1,AF4,0)+IF(AE4=4,AF4/4-4.5,0)+IF(AE4=5,AF4/5-6,0)+IF(AE4=6,AF4/6-7.5,0)+IF(AE4=7,AF4/7-9,0)+IF(AE4=8,AF4/8-10.5,0) -> 3
C5: 4 | D5: 3 | E5: 4 | F5: 4 | G5: 4 | H5: 5 | I5: 3 | J5: 4 | K5: 5 | L5: 4 | M5: 5 | N5: 4 | O5: 4 | P5: 3 | Q5: 5 | R5: 4 | S5: 3 | T5: 4 | Y5: =A8 -> DEY | Z5: =U57 -> 10 | AA5: =RANK(Z5,$Z$4:$Z$11,0) -> 6 | AD5: =IF(AA5=1,24,0)+(IF(AA5=2,21,0))+(IF(AA5=3,18,0))+(IF(AA5=4,15,0))+(IF(AA5=5,12,0))+(IF(AA5=6,9,0))+(IF(AA5=7,6,0))+(IF(AA5=8,3,0)) -> 9 | AE5: =COUNTIF($AD$4:$AD$11,AD5) -> 2 | AF5: =SUMIF($AD$4:$AD$11,AD5) -> 18 | AG5: =IF(AE5=3,AF5/3-3,0)+IF(AE5=2,AF5/2-1.5,0)+IF(AE5=1,AF5,0)+IF(AE5=4,AF5/4-4.5,0)+IF(AE5=5,AF5/5-6,0)+IF(AE5=6,AF5/6-7.5,0)+IF(AE5=7,AF5/7-9,0)+IF(AE5=8,AF5/8-10.5,0) -> 7.5
C6: 16 | D6: 8 | E6: 2 | F6: 18 | G6: 4 | H6: 12 | I6: 6 | J6: 10 | K6: 14 | L6: 11 | M6: 1 | N6: 5 | O6: 15 | P6: 13 | Q6: 7 | R6: 17 | S6: 3 | T6: 9 | Y6: =A9 -> DONOVAN | Z6: =U58 -> 32 | AA6: =RANK(Z6,$Z$4:$Z$11,0) -> 3 | AD6: =IF(AA6=1,24,0)+(IF(AA6=2,21,0))+(IF(AA6=3,18,0))+(IF(AA6=4,15,0))+(IF(AA6=5,12,0))+(IF(AA6=6,9,0))+(IF(AA6=7,6,0))+(IF(AA6=8,3,0)) -> 18 | AE6: =COUNTIF($AD$4:$AD$11,AD6) -> 1 | AF6: =SUMIF($AD$4:$AD$11,AD6) -> 18 | AG6: =IF(AE6=3,AF6/3-3,0)+IF(AE6=2,AF6/2-1.5,0)+IF(AE6=1,AF6,0)+IF(AE6=4,AF6/4-4.5,0)+IF(AE6=5,AF6/5-6,0)+IF(AE6=6,AF6/6-7.5,0)+IF(AE6=7,AF6/7-9,0)+IF(AE6=8,AF6/8-10.5,0) -> 18
A7: BELLIS | B7: 18 | C7: 8 | D7: 2 | E7: 8 | F7: 8 | G7: 8 | H7: 8 | I7: 8 | J7: 8 | K7: 2 | L7: 8 | M7: 8 | N7: 8 | O7: 8 | P7: 8 | Q7: 8 | R7: 8 | S7: 8 | T7: 9 | U7: =SUM(C7:T7) -> 133 | Y7: =A10 -> FINDLAY | Z7: =U59 -> 39 | AA7: =RANK(Z7,$Z$4:$Z$11,0) -> 1 | AD7: =IF(AA7=1,24,0)+(IF(AA7=2,21,0))+(IF(AA7=3,18,0))+(IF(AA7=4,15,0))+(IF(AA7=5,12,0))+(IF(AA7=6,9,0))+(IF(AA7=7,6,0))+(IF(AA7=8,3,0)) -> 24 | AE7: =COUNTIF($AD$4:$AD$11,AD7) -> 2 | AF7: =SUMIF($AD$4:$AD$11,AD7) -> 48 | AG7: =IF(AE7=3,AF7/3-3,0)+IF(AE7=2,AF7/2-1.5,0)+IF(AE7=1,AF7,0)+IF(AE7=4,AF7/4-4.5,0)+IF(AE7=5,AF7/5-6,0)+IF(AE7=6,AF7/6-7.5,0)+IF(AE7=7,AF7/7-9,0)+IF(AE7=8,AF7/8-10.5,0) -> 22.5
A8: DEY | B8: 18 | C8: 7 | D8: 7 | E8: 7 | F8: 7 | G8: 7 | H8: 1 | I8: 1 | J8: 1 | K8: 9 | L8: 9 | M8: 9 | N8: 9 | O8: 9 | P8: 9 | Q8: 9 | R8: 9 | S8: 9 | T8: 9 | U8: =SUM(C8:T8) -> 128 | Y8: =A11 -> HOLLANDS | Z8: =U60 -> 39 | AA8: =RANK(Z8,$Z$4:$Z$11,0) -> 1 | AD8: =IF(AA8=1,24,0)+(IF(AA8=2,21,0))+(IF(AA8=3,18,0))+(IF(AA8=4,15,0))+(IF(AA8=5,12,0))+(IF(AA8=6,9,0))+(IF(AA8=7,6,0))+(IF(AA8=8,3,0)) -> 24 | AE8: =COUNTIF($AD$4:$AD$11,AD8) -> 2 | AF8: =SUMIF($AD$4:$AD$11,AD8) -> 48 | AG8: =IF(AE8=3,AF8/3-3,0)+IF(AE8=2,AF8/2-1.5,0)+IF(AE8=1,AF8,0)+IF(AE8=4,AF8/4-4.5,0)+IF(AE8=5,AF8/5-6,0)+IF(AE8=6,AF8/6-7.5,0)+IF(AE8=7,AF8/7-9,0)+IF(AE8=8,AF8/8-10.5,0) -> 22.5
A9: DONOVAN | B9: 18 | C9: 4 | D9: 9 | E9: 3 | F9: 2 | G9: 4 | H9: 4 | I9: 4 | J9: 4 | K9: 4 | L9: 4 | M9: 4 | N9: 4 | O9: 4 | P9: 4 | Q9: 4 | R9: 4 | S9: 4 | T9: 8 | U9: =SUM(C9:T9) -> 78 | Y9: =A12 -> LAING | Z9: =U61 -> 21 | AA9: =RANK(Z9,$Z$4:$Z$11,0) -> 4 | AD9: =IF(AA9=1,24,0)+(IF(AA9=2,21,0))+(IF(AA9=3,18,0))+(IF(AA9=4,15,0))+(IF(AA9=5,12,0))+(IF(AA9=6,9,0))+(IF(AA9=7,6,0))+(IF(AA9=8,3,0)) -> 15 | AE9: =COUNTIF($AD$4:$AD$11,AD9) -> 1 | AF9: =SUMIF($AD$4:$AD$11,AD9) -> 15 | AG9: =IF(AE9=3,AF9/3-3,0)+IF(AE9=2,AF9/2-1.5,0)+IF(AE9=1,AF9,0)+IF(AE9=4,AF9/4-4.5,0)+IF(AE9=5,AF9/5-6,0)+IF(AE9=6,AF9/6-7.5,0)+IF(AE9=7,AF9/7-9,0)+IF(AE9=8,AF9/8-10.5,0) -> 15
A10: FINDLAY | B10: 18 | C10: 2 | D10: 3 | E10: 6 | F10: 3 | G10: 2 | H10: 2 | I10: 2 | J10: 1 | K10: 4 | L10: 2 | M10: 2 | N10: 2 | O10: 2 | P10: 2 | Q10: 6 | R10: 6 | S10: 6 | T10: 7 | U10: =SUM(C10:T10) -> 60 | Y10: =A13 -> REILLY | Z10: =U62 -> 12 | AA10: =RANK(Z10,$Z$4:$Z$11,0) -> 5 | AD10: =IF(AA10=1,24,0)+(IF(AA10=2,21,0))+(IF(AA10=3,18,0))+(IF(AA10=4,15,0))+(IF(AA10=5,12,0))+(IF(AA10=6,9,0))+(IF(AA10=7,6,0))+(IF(AA10=8,3,0)) -> 12 | AE10: =COUNTIF($AD$4:$AD$11,AD10) -> 1 | AF10: =SUMIF($AD$4:$AD$11,AD10) -> 12 | AG10: =IF(AE10=3,AF10/3-3,0)+IF(AE10=2,AF10/2-1.5,0)+IF(AE10=1,AF10,0)+IF(AE10=4,AF10/4-4.5,0)+IF(AE10=5,AF10/5-6,0)+IF(AE10=6,AF10/6-7.5,0)+IF(AE10=7,AF10/7-9,0)+IF(AE10=8,AF10/8-10.5,0) -> 12
A11: HOLLANDS | B11: 18 | C11: 2 | D11: 3 | E11: 6 | F11: 3 | G11: 2 | H11: 2 | I11: 2 | J11: 1 | K11: 4 | L11: 2 | M11: 2 | N11: 2 | O11: 2 | P11: 2 | Q11: 6 | R11: 6 | S11: 6 | T11: 7 | U11: =SUM(C11:T11) -> 60 | Y11: =A14 -> STONES | Z11: =U63 -> 10 | AA11: =RANK(Z11,$Z$4:$Z$11,0) -> 6 | AD11: =IF(AA11=1,24,0)+(IF(AA11=2,21,0))+(IF(AA11=3,18,0))+(IF(AA11=4,15,0))+(IF(AA11=5,12,0))+(IF(AA11=6,9,0))+(IF(AA11=7,6,0))+(IF(AA11=8,3,0)) -> 9 | AE11: =COUNTIF($AD$4:$AD$11,AD11) -> 2 | AF11: =SUMIF($AD$4:$AD$11,AD11) -> 18 | AG11: =IF(AE11=3,AF11/3-3,0)+IF(AE11=2,AF11/2-1.5,0)+IF(AE11=1,AF11,0)+IF(AE11=4,AF11/4-4.5,0)+IF(AE11=5,AF11/5-6,0)+IF(AE11=6,AF11/6-7.5,0)+IF(AE11=7,AF11/7-9,0)+IF(AE11=8,AF11/8-10.5,0) -> 7.5
A12: LAING | B12: 18 | C12: 7 | D12: 6 | E12: 4 | F12: 4 | G12: 3 | H12: 4 | I12: 7 | J12: 2 | K12: 4 | L12: 5 | M12: 5 | N12: 5 | O12: 5 | P12: 5 | Q12: 5 | R12: 6 | S12: 7 | T12: 6 | U12: =SUM(C12:T12) -> 90
A13: REILLY | B13: 18 | C13: 7 | D13: 5 | E13: 7 | F13: 7 | G13: 7 | H13: 1 | I13: 1 | J13: 7 | K13: 7 | L13: 7 | M13: 7 | N13: 7 | O13: 7 | P13: 7 | Q13: 7 | R13: 6 | S13: 7 | T13: 5 | U13: =SUM(C13:T13) -> 109
A14: STONES | B14: 18 | C14: 7 | D14: 4 | E14: 7 | F14: 7 | G14: 7 | H14: 7 | I14: 7 | J14: 7 | K14: 1 | L14: 7 | M14: 7 | N14: 7 | O14: 7 | P14: 7 | Q14: 7 | R14: 7 | S14: 7 | T14: 4 | U14: =SUM(C14:T14) -> 114 | Y14: =Y4 -> BELLIS | Z14: =Z4 -> 5 | AA14: =AG4 -> 3 | AB14: =RANK(Z14,$Z$14:$Z$21,0)+COUNTIF($Z$14:Z14,Z14)-1 -> 8 | AD14: 1 | AE14: =INDEX($Y$14:$AB$21,MATCH(AD14,$AB$14:$AB$21,0),1) -> FINDLAY | AF14: =INDEX($Y$14:$AB$21,MATCH(AD14,$AB$14:$AB$21,0),2) -> 39 | AG14: =INDEX($Y$14:$AB$21,MATCH(AD14,$AB$14:$AB$21,0),3) -> 22.5
Y15: =Y5 -> DEY | Z15: =Z5 -> 10 | AA15: =AG5 -> 7.5 | AB15: =RANK(Z15,$Z$14:$Z$21,0)+COUNTIF($Z$14:Z15,Z15)-1 -> 6 | AD15: 2 | AE15: =INDEX($Y$14:$AB$21,MATCH(AD15,$AB$14:$AB$21,0),1) -> HOLLANDS | AF15: =INDEX($Y$14:$AB$21,MATCH(AD15,$AB$14:$AB$21,0),2) -> 39 | AG15: =INDEX($Y$14:$AB$21,MATCH(AD15,$AB$14:$AB$21,0),3) -> 22.5
C16: =C4 -> 1 | D16: =D4 -> 2 | E16: =E4 -> 3 | F16: =F4 -> 4 | G16: =G4 -> 5 | H16: =H4 -> 6 | I16: =I4 -> 7 | J16: =J4 -> 8 | ... T16: =T4 -> 18 | U16: TOTAL | V16: HCP STRKS | Y16: =Y6 -> DONOVAN | Z16: =Z6 -> 32 | AA16: =AG6 -> 18 | AB16: =RANK(Z16,$Z$14:$Z$21,0)+COUNTIF($Z$14:Z16,Z16)-1 -> 3 | AD16: 3 | AE16: =INDEX($Y$14:$AB$21,MATCH(AD16,$AB$14:$AB$21,0),1) -> DONOVAN | AF16: =INDEX($Y$14:$AB$21,MATCH(AD16,$AB$14:$AB$21,0),2) -> 32 | AG16: =INDEX($Y$14:$AB$21,MATCH(AD16,$AB$14:$AB$21,0),3) -> 18
C17: =C5 -> 4 | D17: =D5 -> 3 | E17: =E5 -> 4 | F17: =F5 -> 4 | G17: =G5 -> 4 | H17: =H5 -> 5 | I17: =I5 -> 3 | J17: =J5 -> 4 | ... T17: =T5 -> 4 | Y17: =Y7 -> FINDLAY | Z17: =Z7 -> 39 | AA17: =AG7 -> 22.5 | AB17: =RANK(Z17,$Z$14:$Z$21,0)+COUNTIF($Z$14:Z17,Z17)-1 -> 1 | AD17: 4 | AE17: =INDEX($Y$14:$AB$21,MATCH(AD17,$AB$14:$AB$21,0),1) -> LAING | AF17: =INDEX($Y$14:$AB$21,MATCH(AD17,$AB$14:$AB$21,0),2) -> 21 | AG17: =INDEX($Y$14:$AB$21,MATCH(AD17,$AB$14:$AB$21,0),3) -> 15
C18: =C6 -> 16 | D18: =D6 -> 8 | E18: =E6 -> 2 | F18: =F6 -> 18 | G18: =G6 -> 4 | H18: =H6 -> 12 | I18: =I6 -> 6 | J18: =J6 -> 10 | ... T18: =T6 -> 9 | Y18: =Y8 -> HOLLANDS | Z18: =Z8 -> 39 | AA18: =AG8 -> 22.5 | AB18: =RANK(Z18,$Z$14:$Z$21,0)+COUNTIF($Z$14:Z18,Z18)-1 -> 2 | AD18: 5 | AE18: =INDEX($Y$14:$AB$21,MATCH(AD18,$AB$14:$AB$21,0),1) -> REILLY | AF18: =INDEX($Y$14:$AB$21,MATCH(AD18,$AB$14:$AB$21,0),2) -> 12 | AG18: =INDEX($Y$14:$AB$21,MATCH(AD18,$AB$14:$AB$21,0),3) -> 12
A19: BELLIS | B19: =B7 -> 18 | C19: =IF($B$19>=C18,"●","")&(IF($B$19-18>=C18,"●","")) -> ● | D19: =IF($B$19>=D18,"●","")&(IF($B$19-18>=D18,"●","")) -> ● | E19: =IF($B$19>=E18,"●","")&(IF($B$19-18>=E18,"●","")) -> ● | F19: =IF($B$19>=F18,"●","")&(IF($B$19-18>=F18,"●","")) -> ● | G19: =IF($B$19>=G18,"●","")&(IF($B$19-18>=G18,"●","")) -> ● | H19: =IF($B$19>=H18,"●","")&(IF($B$19-18>=H18,"●","")) -> ● | I19: =IF($B$19>=I18,"●","")&(IF($B$19-18>=I18,"●","")) -> ● | J19: =IF($B$19>=J18,"●","")&(IF($B$19-18>=J18,"●","")) -> ● | ... T19: =IF($B$19>=T18,"●","")&(IF($B$19-18>=T18,"●","")) -> ● | Y19: =Y9 -> LAING | Z19: =Z9 -> 21 | AA19: =AG9 -> 15 | AB19: =RANK(Z19,$Z$14:$Z$21,0)+COUNTIF($Z$14:Z19,Z19)-1 -> 4 | AD19: 6 | AE19: =INDEX($Y$14:$AB$21,MATCH(AD19,$AB$14:$AB$21,0),1) -> DEY | AF19: =INDEX($Y$14:$AB$21,MATCH(AD19,$AB$14:$AB$21,0),2) -> 10 | AG19: =INDEX($Y$14:$AB$21,MATCH(AD19,$AB$14:$AB$21,0),3) -> 7.5
A20: DEY | B20: =B8 -> 18 | C20: =IF($B$20>=C18,"●","")&(IF($B$20-18>=C18,"●","")) -> ● | D20: =IF($B$20>=D18,"●","")&(IF($B$20-18>=D18,"●","")) -> ● | E20: =IF($B$20>=E18,"●","")&(IF($B$20-18>=E18,"●","")) -> ● | F20: =IF($B$20>=F18,"●","")&(IF($B$20-18>=F18,"●","")) -> ● | G20: =IF($B$20>=G18,"●","")&(IF($B$20-18>=G18,"●","")) -> ● | H20: =IF($B$20>=H18,"●","")&(IF($B$20-18>=H18,"●","")) -> ● | I20: =IF($B$20>=I18,"●","")&(IF($B$20-18>=I18,"●","")) -> ● | J20: =IF($B$20>=J18,"●","")&(IF($B$20-18>=J18,"●","")) -> ● | ... T20: =IF($B$20>=T18,"●","")&(IF($B$20-18>=T18,"●","")) -> ● | Y20: =Y10 -> REILLY | Z20: =Z10 -> 12 | AA20: =AG10 -> 12 | AB20: =RANK(Z20,$Z$14:$Z$21,0)+COUNTIF($Z$14:Z20,Z20)-1 -> 5 | AD20: 7 | AE20: =INDEX($Y$14:$AB$21,MATCH(AD20,$AB$14:$AB$21,0),1) -> STONES | AF20: =INDEX($Y$14:$AB$21,MATCH(AD20,$AB$14:$AB$21,0),2) -> 10 | AG20: =INDEX($Y$14:$AB$21,MATCH(AD20,$AB$14:$AB$21,0),3) -> 7.5
A21: DONOVAN | B21: =B9 -> 18 | C21: =IF($B$21>=C18,"●","")&(IF($B$21-18>=C18,"●","")) -> ● | D21: =IF($B$21>=D18,"●","")&(IF($B$21-18>=D18,"●","")) -> ● | E21: =IF($B$21>=E18,"●","")&(IF($B$21-18>=E18,"●","")) -> ● | F21: =IF($B$21>=F18,"●","")&(IF($B$21-18>=F18,"●","")) -> ● | G21: =IF($B$21>=G18,"●","")&(IF($B$21-18>=G18,"●","")) -> ● | H21: =IF($B$21>=H18,"●","")&(IF($B$21-18>=H18,"●","")) -> ● | I21: =IF($B$21>=I18,"●","")&(IF($B$21-18>=I18,"●","")) -> ● | J21: =IF($B$21>=J18,"●","")&(IF($B$21-18>=J18,"●","")) -> ● | ... T21: =IF($B$21>=T18,"●","")&(IF($B$21-18>=T18,"●","")) -> ● | Y21: =Y11 -> STONES | Z21: =Z11 -> 10 | AA21: =AG11 -> 7.5 | AB21: =RANK(Z21,$Z$14:$Z$21,0)+COUNTIF($Z$14:Z21,Z21)-1 -> 7 | AD21: 8 | AE21: =INDEX($Y$14:$AB$21,MATCH(AD21,$AB$14:$AB$21,0),1) -> BELLIS | AF21: =INDEX($Y$14:$AB$21,MATCH(AD21,$AB$14:$AB$21,0),2) -> 5 | AG21: =INDEX($Y$14:$AB$21,MATCH(AD21,$AB$14:$AB$21,0),3) -> 3
A22: FINDLAY | B22: =B10 -> 18 | C22: =IF($B$22>=C18,"●","")&(IF($B$22-18>=C18,"●","")) -> ● | D22: =IF($B$22>=D18,"●","")&(IF($B$22-18>=D18,"●","")) -> ● | E22: =IF($B$22>=E18,"●","")&(IF($B$22-18>=E18,"●","")) -> ● | F22: =IF($B$22>=F18,"●","")&(IF($B$22-18>=F18,"●","")) -> ● | G22: =IF($B$22>=G18,"●","")&(IF($B$22-18>=G18,"●","")) -> ● | H22: =IF($B$22>=H18,"●","")&(IF($B$22-18>=H18,"●","")) -> ● | I22: =IF($B$22>=I18,"●","")&(IF($B$22-18>=I18,"●","")) -> ● | J22: =IF($B$22>=J18,"●","")&(IF($B$22-18>=J18,"●","")) -> ● | ... T22: =IF($B$22>=T18,"●","")&(IF($B$22-18>=T18,"●","")) -> ●
A23: HOLLANDS | B23: =B11 -> 18 | C23: =IF($B$23>=C18,"●","")&(IF($B$23-18>=C18,"●","")) -> ● | D23: =IF($B$23>=D18,"●","")&(IF($B$23-18>=D18,"●","")) -> ● | E23: =IF($B$23>=E18,"●","")&(IF($B$23-18>=E18,"●","")) -> ● | F23: =IF($B$23>=F18,"●","")&(IF($B$23-18>=F18,"●","")) -> ● | G23: =IF($B$23>=G18,"●","")&(IF($B$23-18>=G18,"●","")) -> ● | H23: =IF($B$23>=H18,"●","")&(IF($B$23-18>=H18,"●","")) -> ● | I23: =IF($B$23>=I18,"●","")&(IF($B$23-18>=I18,"●","")) -> ● | J23: =IF($B$23>=J18,"●","")&(IF($B$23-18>=J18,"●","")) -> ● | ... T23: =IF($B$23>=T18,"●","")&(IF($B$23-18>=T18,"●","")) -> ●
A24: LAING | B24: =B12 -> 18 | C24: =IF($B$24>=C18,"●","")&(IF($B$24-18>=C18,"●","")) -> ● | D24: =IF($B$24>=D18,"●","")&(IF($B$24-18>=D18,"●","")) -> ● | E24: =IF($B$24>=E18,"●","")&(IF($B$24-18>=E18,"●","")) -> ● | F24: =IF($B$24>=F18,"●","")&(IF($B$24-18>=F18,"●","")) -> ● | G24: =IF($B$24>=G18,"●","")&(IF($B$24-18>=G18,"●","")) -> ● | H24: =IF($B$24>=H18,"●","")&(IF($B$24-18>=H18,"●","")) -> ● | I24: =IF($B$24>=I18,"●","")&(IF($B$24-18>=I18,"●","")) -> ● | J24: =IF($B$24>=J18,"●","")&(IF($B$24-18>=J18,"●","")) -> ● | ... T24: =IF($B$24>=T18,"●","")&(IF($B$24-18>=T18,"●","")) -> ●
A25: REILLY | B25: =B13 -> 18 | C25: =IF($B$25>=C18,"●","")&(IF($B$25-18>=C18,"●","")) -> ● | D25: =IF($B$25>=D18,"●","")&(IF($B$25-18>=D18,"●","")) -> ● | E25: =IF($B$25>=E18,"●","")&(IF($B$25-18>=E18,"●","")) -> ● | F25: =IF($B$25>=F18,"●","")&(IF($B$25-18>=F18,"●","")) -> ● | G25: =IF($B$25>=G18,"●","")&(IF($B$25-18>=G18,"●","")) -> ● | H25: =IF($B$25>=H18,"●","")&(IF($B$25-18>=H18,"●","")) -> ● | I25: =IF($B$25>=I18,"●","")&(IF($B$25-18>=I18,"●","")) -> ● | J25: =IF($B$25>=J18,"●","")&(IF($B$25-18>=J18,"●","")) -> ● | ... T25: =IF($B$25>=T18,"●","")&(IF($B$25-18>=T18,"●","")) -> ●
A26: STONES | B26: =B14 -> 18 | C26: =IF($B$26>=C18,"●","")&(IF($B$26-18>=C18,"●","")) -> ● | D26: =IF($B$26>=D18,"●","")&(IF($B$26-18>=D18,"●","")) -> ● | E26: =IF($B$26>=E18,"●","")&(IF($B$26-18>=E18,"●","")) -> ● | F26: =IF($B$26>=F18,"●","")&(IF($B$26-18>=F18,"●","")) -> ● | G26: =IF($B$26>=G18,"●","")&(IF($B$26-18>=G18,"●","")) -> ● | H26: =IF($B$26>=H18,"●","")&(IF($B$26-18>=H18,"●","")) -> ● | I26: =IF($B$26>=I18,"●","")&(IF($B$26-18>=I18,"●","")) -> ● | J26: =IF($B$26>=J18,"●","")&(IF($B$26-18>=J18,"●","")) -> ● | ... T26: =IF($B$26>=T18,"●","")&(IF($B$26-18>=T18,"●","")) -> ●
C28: =C16 -> 1 | D28: =D16 -> 2 | E28: =E16 -> 3 | F28: =F16 -> 4 | G28: =G16 -> 5 | H28: =H16 -> 6 | I28: =I16 -> 7 | J28: =J16 -> 8 | ... T28: =T16 -> 18 | U28: TOTAL | V28: NET SCORE
C29: =C17 -> 4 | D29: =D17 -> 3 | E29: =E17 -> 4 | F29: =F17 -> 4 | G29: =G17 -> 4 | H29: =H17 -> 5 | I29: =I17 -> 3 | J29: =J17 -> 4 | ... T29: =T17 -> 4
C30: =C18 -> 16 | D30: =D18 -> 8 | E30: =E18 -> 2 | F30: =F18 -> 18 | G30: =G18 -> 4 | H30: =H18 -> 12 | I30: =I18 -> 6 | J30: =J18 -> 10 | ... T30: =T18 -> 9
A31: BELLIS | B31: 8 | C31: =C7+IF(C19="●",-1)+IF(C19="●●",-2) -> 7 | D31: =D7+IF(D19="●",-1)+IF(D19="●●",-2) -> 1 | E31: =E7+IF(E19="●",-1)+IF(E19="●●",-2) -> 7 | F31: =F7+IF(F19="●",-1)+IF(F19="●●",-2) -> 7 | G31: =G7+IF(G19="●",-1)+IF(G19="●●",-2) -> 7 | H31: =H7+IF(H19="●",-1)+IF(H19="●●",-2) -> 7 | I31: =I7+IF(I19="●",-1)+IF(I19="●●",-2) -> 7 | J31: =J7+IF(J19="●",-1)+IF(J19="●●",-2) -> 7 | ... T31: =T7+IF(T19="●",-1)+IF(T19="●●",-2) -> 8 | U31: =SUM(C31:T31) -> 115
A32: DEY | B32: 17 | C32: =C8+IF(C20="●",-1)+IF(C20="●●",-2) -> 6 | D32: =D8+IF(D20="●",-1)+IF(D20="●●",-2) -> 6 | E32: =E8+IF(E20="●",-1)+IF(E20="●●",-2) -> 6 | F32: =F8+IF(F20="●",-1)+IF(F20="●●",-2) -> 6 | G32: =G8+IF(G20="●",-1)+IF(G20="●●",-2) -> 6 | H32: =H8+IF(H20="●",-1)+IF(H20="●●",-2) -> 0 | I32: =I8+IF(I20="●",-1)+IF(I20="●●",-2) -> 0 | J32: =J8+IF(J20="●",-1)+IF(J20="●●",-2) -> 0 | ... T32: =T8+IF(T20="●",-1)+IF(T20="●●",-2) -> 8 | U32: =SUM(C32:T32) -> 110
A33: DONOVAN | B33: 12 | C33: =C9+IF(C21="●",-1)+IF(C21="●●",-2) -> 3 | D33: =D9+IF(D21="●",-1)+IF(D21="●●",-2) -> 8 | E33: =E9+IF(E21="●",-1)+IF(E21="●●",-2) -> 2 | F33: =F9+IF(F21="●",-1)+IF(F21="●●",-2) -> 1 | G33: =G9+IF(G21="●",-1)+IF(G21="●●",-2) -> 3 | H33: =H9+IF(H21="●",-1)+IF(H21="●●",-2) -> 3 | I33: =I9+IF(I21="●",-1)+IF(I21="●●",-2) -> 3 | J33: =J9+IF(J21="●",-1)+IF(J21="●●",-2) -> 3 | ... T33: =T9+IF(T21="●",-1)+IF(T21="●●",-2) -> 7 | U33: =SUM(C33:T33) -> 60
A34: FINDLAY | B34: 13 | C34: =C10+IF(C22="●",-1)+IF(C22="●●",-2) -> 1 | D34: =D10+IF(D22="●",-1)+IF(D22="●●",-2) -> 2 | E34: =E10+IF(E22="●",-1)+IF(E22="●●",-2) -> 5 | F34: =F10+IF(F22="●",-1)+IF(F22="●●",-2) -> 2 | G34: =G10+IF(G22="●",-1)+IF(G22="●●",-2) -> 1 | H34: =H10+IF(H22="●",-1)+IF(H22="●●",-2) -> 1 | I34: =I10+IF(I22="●",-1)+IF(I22="●●",-2) -> 1 | J34: =J10+IF(J22="●",-1)+IF(J22="●●",-2) -> 0 | ... T34: =T10+IF(T22="●",-1)+IF(T22="●●",-2) -> 6 | U34: =SUM(C34:T34) -> 42
A35: HOLLANDS | B35: 9 | C35: =C11+IF(C23="●",-1)+IF(C23="●●",-2) -> 1 | D35: =D11+IF(D23="●",-1)+IF(D23="●●",-2) -> 2 | E35: =E11+IF(E23="●",-1)+IF(E23="●●",-2) -> 5 | F35: =F11+IF(F23="●",-1)+IF(F23="●●",-2) -> 2 | G35: =G11+IF(G23="●",-1)+IF(G23="●●",-2) -> 1 | H35: =H11+IF(H23="●",-1)+IF(H23="●●",-2) -> 1 | I35: =I11+IF(I23="●",-1)+IF(I23="●●",-2) -> 1 | J35: =J11+IF(J23="●",-1)+IF(J23="●●",-2) -> 0 | ... T35: =T11+IF(T23="●",-1)+IF(T23="●●",-2) -> 6 | U35: =SUM(C35:T35) -> 42
A36: LAING | B36: 3 | C36: =C12+IF(C24="●",-1)+IF(C24="●●",-2) -> 6 | D36: =D12+IF(D24="●",-1)+IF(D24="●●",-2) -> 5 | E36: =E12+IF(E24="●",-1)+IF(E24="●●",-2) -> 3 | F36: =F12+IF(F24="●",-1)+IF(F24="●●",-2) -> 3 | G36: =G12+IF(G24="●",-1)+IF(G24="●●",-2) -> 2 | H36: =H12+IF(H24="●",-1)+IF(H24="●●",-2) -> 3 | I36: =I12+IF(I24="●",-1)+IF(I24="●●",-2) -> 6 | J36: =J12+IF(J24="●",-1)+IF(J24="●●",-2) -> 1 | ... T36: =T12+IF(T24="●",-1)+IF(T24="●●",-2) -> 5 | U36: =SUM(C36:T36) -> 72
A37: REILLY | B37: 3 | C37: =C13+IF(C25="●",-1)+IF(C25="●●",-2) -> 6 | D37: =D13+IF(D25="●",-1)+IF(D25="●●",-2) -> 4 | E37: =E13+IF(E25="●",-1)+IF(E25="●●",-2) -> 6 | F37: =F13+IF(F25="●",-1)+IF(F25="●●",-2) -> 6 | G37: =G13+IF(G25="●",-1)+IF(G25="●●",-2) -> 6 | H37: =H13+IF(H25="●",-1)+IF(H25="●●",-2) -> 0 | I37: =I13+IF(I25="●",-1)+IF(I25="●●",-2) -> 0 | J37: =J13+IF(J25="●",-1)+IF(J25="●●",-2) -> 6 | ... T37: =T13+IF(T25="●",-1)+IF(T25="●●",-2) -> 4 | U37: =SUM(C37:T37) -> 91
A38: STONES | B38: 15 | C38: =C14+IF(C26="●",-1)+IF(C26="●●",-2) -> 6 | D38: =D14+IF(D26="●",-1)+IF(D26="●●",-2) -> 3 | E38: =E14+IF(E26="●",-1)+IF(E26="●●",-2) -> 6 | F38: =F14+IF(F26="●",-1)+IF(F26="●●",-2) -> 6 | G38: =G14+IF(G26="●",-1)+IF(G26="●●",-2) -> 6 | H38: =H14+IF(H26="●",-1)+IF(H26="●●",-2) -> 6 | I38: =I14+IF(I26="●",-1)+IF(I26="●●",-2) -> 6 | J38: =J14+IF(J26="●",-1)+IF(J26="●●",-2) -> 6 | ... T38: =T14+IF(T26="●",-1)+IF(T26="●●",-2) -> 3 | U38: =SUM(C38:T38) -> 96
C41: =C28 -> 1 | D41: =D28 -> 2 | E41: =E28 -> 3 | F41: =F28 -> 4 | G41: =G28 -> 5 | H41: =H28 -> 6 | I41: =I28 -> 7 | J41: =J28 -> 8 | ... T41: =T28 -> 18 | U41: TOTAL | V41: LOWEST NETS
C42: =C29 -> 4 | D42: =D29 -> 3 | E42: =E29 -> 4 | F42: =F29 -> 4 | G42: =G29 -> 4 | H42: =H29 -> 5 | I42: =I29 -> 3 | J42: =J29 -> 4 | ... T42: =T29 -> 4
C43: =C30 -> 16 | D43: =D30 -> 8 | E43: =E30 -> 2 | F43: =F30 -> 18 | G43: =G30 -> 4 | H43: =H30 -> 12 | I43: =I30 -> 6 | J43: =J30 -> 10 | ... T43: =T30 -> 9
B44: LOWEST | C44: {=IFERROR(SMALL(IF(FREQUENCY(C$31:C$38, C$31:C$38)>0, C$31:C$38), ROW(A1)),"")} -> 1 | D44: {=IFERROR(SMALL(IF(FREQUENCY(D$31:D$38, D$31:D$38)>0, D$31:D$38), ROW(B1)),"")} -> 1 | E44: {=IFERROR(SMALL(IF(FREQUENCY(E$31:E$38, E$31:E$38)>0, E$31:E$38), ROW(C1)),"")} -> 2 | F44: {=IFERROR(SMALL(IF(FREQUENCY(F$31:F$38, F$31:F$38)>0, F$31:F$38), ROW(D1)),"")} -> 1 | G44: {=IFERROR(SMALL(IF(FREQUENCY(G$31:G$38, G$31:G$38)>0, G$31:G$38), ROW(E1)),"")} -> 1 | H44: {=IFERROR(SMALL(IF(FREQUENCY(H$31:H$38, H$31:H$38)>0, H$31:H$38), ROW(F1)),"")} -> 0 | I44: {=IFERROR(SMALL(IF(FREQUENCY(I$31:I$38, I$31:I$38)>0, I$31:I$38), ROW(G1)),"")} -> 0 | J44: {=IFERROR(SMALL(IF(FREQUENCY(J$31:J$38, J$31:J$38)>0, J$31:J$38), ROW(H1)),"")} -> 0 | ... T44: {=IFERROR(SMALL(IF(FREQUENCY(T$31:T$38, T$31:T$38)>0, T$31:T$38), ROW(R1)),"")} -> 3
B45: 2ND LOWEST | C45: {=IFERROR(SMALL(IF(FREQUENCY(C$31:C$38, C$31:C$38)>0, C$31:C$38), ROW(A2)),"")} -> 3 | D45: {=IFERROR(SMALL(IF(FREQUENCY(D$31:D$38, D$31:D$38)>0, D$31:D$38), ROW(B2)),"")} -> 2 | E45: {=IFERROR(SMALL(IF(FREQUENCY(E$31:E$38, E$31:E$38)>0, E$31:E$38), ROW(C2)),"")} -> 3 | F45: {=IFERROR(SMALL(IF(FREQUENCY(F$31:F$38, F$31:F$38)>0, F$31:F$38), ROW(D2)),"")} -> 2 | G45: {=IFERROR(SMALL(IF(FREQUENCY(G$31:G$38, G$31:G$38)>0, G$31:G$38), ROW(E2)),"")} -> 2 | H45: {=IFERROR(SMALL(IF(FREQUENCY(H$31:H$38, H$31:H$38)>0, H$31:H$38), ROW(F2)),"")} -> 1 | I45: {=IFERROR(SMALL(IF(FREQUENCY(I$31:I$38, I$31:I$38)>0, I$31:I$38), ROW(G2)),"")} -> 1 | J45: {=IFERROR(SMALL(IF(FREQUENCY(J$31:J$38, J$31:J$38)>0, J$31:J$38), ROW(H2)),"")} -> 1 | ... T45: {=IFERROR(SMALL(IF(FREQUENCY(T$31:T$38, T$31:T$38)>0, T$31:T$38), ROW(R2)),"")} -> 4
...

Sheet Round3
A2: Round 3 - Tournament Standings
B3: TOURNAMENT STANDINGS
A6: RANK | B6: PLAYER | C6: SCORE | D6: POINTS
A7: ='RND 3 MSTB'!AD14 -> 1 | B7: ='RND 3 MSTB'!AE14 -> STONES | C7: ='RND 3 MSTB'!AF14 -> -6 | D7: ='RND 3 MSTB'!AG14 -> 24
A8: ='RND 3 MSTB'!AD15 -> 2 | B8: ='RND 3 MSTB'!AE15 -> REILLY | C8: ='RND 3 MSTB'!AF15 -> -7 | D8: ='RND 3 MSTB'!AG15 -> 21
A9: ='RND 3 MSTB'!AD16 -> 3 | B9: ='RND 3 MSTB'!AE16 -> LAING | C9: ='RND 3 MSTB'!AF16 -> -8 | D9: ='RND 3 MSTB'!AG16 -> 18
A10: ='RND 3 MSTB'!AD17 -> 4 | B10: ='RND 3 MSTB'!AE17 -> HOLLANDS | C10: ='RND 3 MSTB'!AF17 -> -9 | D10: ='RND 3 MSTB'!AG17 -> 15
A11: ='RND 3 MSTB'!AD18 -> 5 | B11: ='RND 3 MSTB'!AE18 -> FINDLAY | C11: ='RND 3 MSTB'!AF18 -> -12 | D11: ='RND 3 MSTB'!AG18 -> 12
A12: ='RND 3 MSTB'!AD19 -> 6 | B12: ='RND 3 MSTB'!AE19 -> DONOVAN | C12: ='RND 3 MSTB'!AF19 -> -15 | D12: ='RND 3 MSTB'!AG19 -> 9
